Workbook

Sheet Маҳаллий банклар
B1: Mamlakat va hamkor banklarga joylashtirilishi mumkin bo‘lgan mablag‘larga limit o‘rnatish tartibiga ilova | C1: Mahalliy banklarga joylashtirilishi mumkin bo‘lgan mablag‘larga limit o‘rnatish modeli
B2: 45839 | C2: ming. so‘m
C3: 1 | D3: 2 | E3: 3 | F3: 4 | G3: 5 | H3: 6 | I3: 7 | J3: 8 | K3: 9 | L3: 10 | M3: 11 | N3: 12 | O3: 13 | P3: 14 | Q3: 15 | R3: 16 | S3: 17 | T3: 18 | U3: 19 | V3: 20 | W3: 21 | X3: 22 | Y3: 23 | Z3: 24 | AA3: 25 | AB3: 26 | AC3: 27 | AD3: 28 | AE3: 29 | AF3: 30 | AG3: 31 | AH3: 32 | AI3: 33 | AJ3: 34 | AK3: 35
A4: № | B4: АКТИВЛАР | C4: АКБ "ASIA ALLIANCE BANK" | D4: АТБ "АГРОБАНК" | E4: АК "Алокабанк" | F4: Anorbank | G4: "Асака" банк | H4: ЧАКБ"ДАВР БАНК" | I4: АКБ Hamkorbank | J4: АКБ "InFinBank" | K4: АИКБ "Ипак Йули" | L4: ИПОТЕКА-БАНК АТИБ | M4: АКБ "Капиталбанк" | N4: АО "КДБ Банк Узбекистан" | O4: АКБ "Мадад Инвест Банк" | P4: АО "Национальный банк ВЭД РУ" | Q4: ЧАКБ "Ориент Финанс" | R4: АО "Пойтахт банк" | S4: АТБ Biznesni rivojlantirish banki | T4: Octobank | U4: Садерат банк | V4: "Гарант банк" АЖ | W4: АКБ "Тибиси банк" | X4: АКБ "Tenge Bank" | Y4: ЧАБ "Трастбанк" | Z4: АКБ "ТУРОНБАНК" | AA4: AVO bank | AB4: АКБ УНИВЕРСАЛ БАНК | AC4: АК УЗПРОМСТРОЙБАНК | AD4: АК Народный банк | AE4: АО "Ziraat Bank Uzbekistan" | AF4: "UZUM BANK" AJ | AG4: Smart bank | AH4: Apex bank | AI4: Hayot bank | AJ4: Yangi bank | AK4: MKBank
A5: 1 | B5: Кассадаги нақд пул ва бошқа тўлов ҳужжатлари | C5: =+IFERROR(VLOOKUP($A5,[1]Лист1!$A$5:$E$1048576,3,0),0) | D5: =+IFERROR(VLOOKUP($A5,'[2]1'!$A$5:$E$1048576,3,0),0) | E5: =+IFERROR(VLOOKUP($A5,'[3]1'!$A$5:$E$1048576,3,0),0) | F5: =+IFERROR(VLOOKUP($A5,[4]Balance!$A$5:$E$1048576,3,0),0) | G5: =+IFERROR(VLOOKUP($A5,'[5]1'!$A$5:$E$1048576,3,0),0) | H5: =+IFERROR(VLOOKUP($A5,[6]Balance!$A$5:$E$1048576,3,0),0) | I5: =+IFERROR(VLOOKUP($A5,[7]Balance!$A$5:$E$1048576,3,0),0) | J5: =+IFERROR(VLOOKUP($A5,'[8]1'!$A$5:$E$1048576,3,0),0) | K5: =+IFERROR(VLOOKUP($A5,'[9]1'!$A$5:$E$1048576,3,0),0) | L5: =+IFERROR(VLOOKUP($A5,'[10]1'!$A$5:$E$1048576,3,0),0) | M5: =+IFERROR(VLOOKUP($A5,'[11]1'!$A$5:$E$1048576,3,0),0) | N5: =+IFERROR(VLOOKUP($A5,[12]Balance!$A$5:$E$1048576,3,0),0) | O5: =+IFERROR(VLOOKUP($A5,'[13]1 т'!$A$5:$E$1048576,3,0),0) | P5: =+IFERROR(VLOOKUP($A5,[14]Balance!$A$5:$E$1048576,3,0),0) | Q5: =+IFERROR(VLOOKUP($A5,[15]Balance!$A$5:$E$1048576,3,0),0) | R5: =+IFERROR(VLOOKUP($A5,'[16]1'!$A$5:$E$1048576,3,0),0) | S5: =+IFERROR(VLOOKUP($A5,'[17]1'!$A$5:$E$1048576,3,0),0) | T5: =+IFERROR(VLOOKUP($A5,'[18]1'!$A$5:$E$1048576,3,0),0) | U5: =+IFERROR(VLOOKUP($A5,[19]Balans!$A$5:$E$1048576,3,0),0) | V5: =+IFERROR(VLOOKUP($A5,'[20]1'!$A$5:$E$1048576,3,0),0) | W5: =+IFERROR(VLOOKUP($A5,[21]Balance!$A$5:$E$1048576,3,0),0) | X5: =+IFERROR(VLOOKUP($A5,'[22]1'!$A$5:$E$1048576,3,0),0) | Y5: =+IFERROR(VLOOKUP($A5,[23]Лист1!$A$5:$E$1048576,3,0),0) | Z5: =+IFERROR(VLOOKUP($A5,'[24]1'!$A$5:$E$1048576,3,0),0) | AA5: =+IFERROR(VLOOKUP($A5,[25]Balance!$A$5:$E$1048576,3,0),0) | AB5: =+IFERROR(VLOOKUP($A5,'[26]1'!$A$5:$E$1048576,3,0),0) | AC5: =+IFERROR(VLOOKUP($A5,'[27]1'!$A$5:$E$1048576,3,0),0) | AD5: =+IFERROR(VLOOKUP($A5,'[28]1'!$A$5:$E$1048576,3,0),0) | AE5: =+IFERROR(VLOOKUP($A5,[29]Лист1!$A$5:$E$1048576,3,0),0) | AF5: =+IFERROR(VLOOKUP($A5,'[30]1'!$A$5:$E$1048576,3,0),0) | AG5: =+IFERROR(VLOOKUP($A5,'[31]1'!$A$5:$E$1048576,3,0),0) | AH5: =+IFERROR(VLOOKUP($A5,'[32]1-жадвал'!$A$5:$E$1048576,3,0),0) | AI5: =+IFERROR(VLOOKUP($A5,[33]Balance!$A$5:$E$1048576,3,0),0) | AJ5: =+IFERROR(VLOOKUP($A5,[34]Balance!$A$5:$E$1048576,3,0),0) | AK5: =+IFERROR(VLOOKUP($A5,'[35]1'!$A$5:$E$1048576,3,0),0)
A6: 2 | B6: Банкнинг Марказий банкдаги маблағлари | C6: =+IFERROR(VLOOKUP($A6,[1]Лист1!$A$5:$E$1048576,3,0),0) | D6: =+IFERROR(VLOOKUP($A6,'[2]1'!$A$5:$E$1048576,3,0),0) | E6: =+IFERROR(VLOOKUP($A6,'[3]1'!$A$5:$E$1048576,3,0),0) | F6: =+IFERROR(VLOOKUP($A6,[4]Balance!$A$5:$E$1048576,3,0),0) | G6: =+IFERROR(VLOOKUP($A6,'[5]1'!$A$5:$E$1048576,3,0),0) | H6: =+IFERROR(VLOOKUP($A6,[6]Balance!$A$5:$E$1048576,3,0),0) | I6: =+IFERROR(VLOOKUP($A6,[7]Balance!$A$5:$E$1048576,3,0),0) | J6: =+IFERROR(VLOOKUP($A6,'[8]1'!$A$5:$E$1048576,3,0),0) | K6: =+IFERROR(VLOOKUP($A6,'[9]1'!$A$5:$E$1048576,3,0),0) | L6: =+IFERROR(VLOOKUP($A6,'[10]1'!$A$5:$E$1048576,3,0),0) | M6: =+IFERROR(VLOOKUP($A6,'[11]1'!$A$5:$E$1048576,3,0),0) | N6: =+IFERROR(VLOOKUP($A6,[12]Balance!$A$5:$E$1048576,3,0),0) | O6: =+IFERROR(VLOOKUP($A6,'[13]1 т'!$A$5:$E$1048576,3,0),0) | P6: =+IFERROR(VLOOKUP($A6,[14]Balance!$A$5:$E$1048576,3,0),0) | Q6: =+IFERROR(VLOOKUP($A6,[15]Balance!$A$5:$E$1048576,3,0),0) | R6: =+IFERROR(VLOOKUP($A6,'[16]1'!$A$5:$E$1048576,3,0),0) | S6: =+IFERROR(VLOOKUP($A6,'[17]1'!$A$5:$E$1048576,3,0),0) | T6: =+IFERROR(VLOOKUP($A6,'[18]1'!$A$5:$E$1048576,3,0),0) | U6: =+IFERROR(VLOOKUP($A6,[19]Balans!$A$5:$E$1048576,3,0),0) | V6: =+IFERROR(VLOOKUP($A6,'[20]1'!$A$5:$E$1048576,3,0),0) | W6: =+IFERROR(VLOOKUP($A6,[21]Balance!$A$5:$E$1048576,3,0),0) | X6: =+IFERROR(VLOOKUP($A6,'[22]1'!$A$5:$E$1048576,3,0),0) | Y6: =+IFERROR(VLOOKUP($A6,[23]Лист1!$A$5:$E$1048576,3,0),0) | Z6: =+IFERROR(VLOOKUP($A6,'[24]1'!$A$5:$E$1048576,3,0),0) | AA6: =+IFERROR(VLOOKUP($A6,[25]Balance!$A$5:$E$1048576,3,0),0) | AB6: =+IFERROR(VLOOKUP($A6,'[26]1'!$A$5:$E$1048576,3,0),0) | AC6: =+IFERROR(VLOOKUP($A6,'[27]1'!$A$5:$E$1048576,3,0),0) | AD6: =+IFERROR(VLOOKUP($A6,'[28]1'!$A$5:$E$1048576,3,0),0) | AE6: =+IFERROR(VLOOKUP($A6,[29]Лист1!$A$5:$E$1048576,3,0),0) | AF6: =+IFERROR(VLOOKUP($A6,'[30]1'!$A$5:$E$1048576,3,0),0) | AG6: =+IFERROR(VLOOKUP($A6,'[31]1'!$A$5:$E$1048576,3,0),0) | AH6: =+IFERROR(VLOOKUP($A6,'[32]1-жадвал'!$A$5:$E$1048576,3,0),0) | AI6: =+IFERROR(VLOOKUP($A6,[33]Balance!$A$5:$E$1048576,3,0),0) | AJ6: =+IFERROR(VLOOKUP($A6,[34]Balance!$A$5:$E$1048576,3,0),0) | AK6: =+IFERROR(VLOOKUP($A6,'[35]1'!$A$5:$E$1048576,3,0),0)
A7: 3 | B7: Бошқа банклар ва молиявий ташкилотлардан олиниши лозим бўлган маблағлар, соф | C7: =+IFERROR(VLOOKUP($A7,[1]Лист1!$A$5:$E$1048576,3,0),0) | D7: =+IFERROR(VLOOKUP($A7,'[2]1'!$A$5:$E$1048576,3,0),0) | E7: =+IFERROR(VLOOKUP($A7,'[3]1'!$A$5:$E$1048576,3,0),0) | F7: =+IFERROR(VLOOKUP($A7,[4]Balance!$A$5:$E$1048576,3,0),0) | G7: =+IFERROR(VLOOKUP($A7,'[5]1'!$A$5:$E$1048576,3,0),0) | H7: =+IFERROR(VLOOKUP($A7,[6]Balance!$A$5:$E$1048576,3,0),0) | I7: =+IFERROR(VLOOKUP($A7,[7]Balance!$A$5:$E$1048576,3,0),0) | J7: =+IFERROR(VLOOKUP($A7,'[8]1'!$A$5:$E$1048576,3,0),0) | K7: =+IFERROR(VLOOKUP($A7,'[9]1'!$A$5:$E$1048576,3,0),0) | L7: =+IFERROR(VLOOKUP($A7,'[10]1'!$A$5:$E$1048576,3,0),0) | M7: =+IFERROR(VLOOKUP($A7,'[11]1'!$A$5:$E$1048576,3,0),0) | N7: =+IFERROR(VLOOKUP($A7,[12]Balance!$A$5:$E$1048576,3,0),0) | O7: =+IFERROR(VLOOKUP($A7,'[13]1 т'!$A$5:$E$1048576,3,0),0) | P7: =+IFERROR(VLOOKUP($A7,[14]Balance!$A$5:$E$1048576,3,0),0) | Q7: =+IFERROR(VLOOKUP($A7,[15]Balance!$A$5:$E$1048576,3,0),0) | R7: =+IFERROR(VLOOKUP($A7,'[16]1'!$A$5:$E$1048576,3,0),0) | S7: =+IFERROR(VLOOKUP($A7,'[17]1'!$A$5:$E$1048576,3,0),0) | T7: =+IFERROR(VLOOKUP($A7,'[18]1'!$A$5:$E$1048576,3,0),0) | U7: =+IFERROR(VLOOKUP($A7,[19]Balans!$A$5:$E$1048576,3,0),0) | V7: =+IFERROR(VLOOKUP($A7,'[20]1'!$A$5:$E$1048576,3,0),0) | W7: =+IFERROR(VLOOKUP($A7,[21]Balance!$A$5:$E$1048576,3,0),0) | X7: =+IFERROR(VLOOKUP($A7,'[22]1'!$A$5:$E$1048576,3,0),0) | Y7: =+IFERROR(VLOOKUP($A7,[23]Лист1!$A$5:$E$1048576,3,0),0) | Z7: =+IFERROR(VLOOKUP($A7,'[24]1'!$A$5:$E$1048576,3,0),0) | AA7: =+IFERROR(VLOOKUP($A7,[25]Balance!$A$5:$E$1048576,3,0),0) | AB7: =+IFERROR(VLOOKUP($A7,'[26]1'!$A$5:$E$1048576,3,0),0) | AC7: =+IFERROR(VLOOKUP($A7,'[27]1'!$A$5:$E$1048576,3,0),0) | AD7: =+IFERROR(VLOOKUP($A7,'[28]1'!$A$5:$E$1048576,3,0),0) | AE7: =+IFERROR(VLOOKUP($A7,[29]Лист1!$A$5:$E$1048576,3,0),0) | AF7: =+IFERROR(VLOOKUP($A7,'[30]1'!$A$5:$E$1048576,3,0),0) | AG7: =+IFERROR(VLOOKUP($A7,'[31]1'!$A$5:$E$1048576,3,0),0) | AH7: =+IFERROR(VLOOKUP($A7,'[32]1-жадвал'!$A$5:$E$1048576,3,0),0) | AI7: =+IFERROR(VLOOKUP($A7,[33]Balance!$A$5:$E$1048576,3,0),0) | AJ7: =+IFERROR(VLOOKUP($A7,[34]Balance!$A$5:$E$1048576,3,0),0) | AK7: =+IFERROR(VLOOKUP($A7,'[35]1'!$A$5:$E$1048576,3,0),0)
A8: 3.1 | B8: Бошқа банклар ва молиявий ташкилотлардан олиниши лозим бўлган маблағлар, брутто | C8: =+IFERROR(VLOOKUP($A8,[1]Лист1!$A$5:$E$1048576,3,0),0) | D8: =+IFERROR(VLOOKUP($A8,'[2]1'!$A$5:$E$1048576,3,0),0) | E8: =+IFERROR(VLOOKUP($A8,'[3]1'!$A$5:$E$1048576,3,0),0) | F8: =+IFERROR(VLOOKUP($A8,[4]Balance!$A$5:$E$1048576,3,0),0) | G8: =+IFERROR(VLOOKUP($A8,'[5]1'!$A$5:$E$1048576,3,0),0) | H8: =+IFERROR(VLOOKUP($A8,[6]Balance!$A$5:$E$1048576,3,0),0) | I8: =+IFERROR(VLOOKUP($A8,[7]Balance!$A$5:$E$1048576,3,0),0) | J8: =+IFERROR(VLOOKUP($A8,'[8]1'!$A$5:$E$1048576,3,0),0) | K8: =+IFERROR(VLOOKUP($A8,'[9]1'!$A$5:$E$1048576,3,0),0) | L8: =+IFERROR(VLOOKUP($A8,'[10]1'!$A$5:$E$1048576,3,0),0) | M8: =+IFERROR(VLOOKUP($A8,'[11]1'!$A$5:$E$1048576,3,0),0) | N8: =+IFERROR(VLOOKUP($A8,[12]Balance!$A$5:$E$1048576,3,0),0) | O8: =+IFERROR(VLOOKUP($A8,'[13]1 т'!$A$5:$E$1048576,3,0),0) | P8: =+IFERROR(VLOOKUP($A8,[14]Balance!$A$5:$E$1048576,3,0),0) | Q8: =+IFERROR(VLOOKUP($A8,[15]Balance!$A$5:$E$1048576,3,0),0) | R8: =+IFERROR(VLOOKUP($A8,'[16]1'!$A$5:$E$1048576,3,0),0) | S8: =+IFERROR(VLOOKUP($A8,'[17]1'!$A$5:$E$1048576,3,0),0) | T8: =+IFERROR(VLOOKUP($A8,'[18]1'!$A$5:$E$1048576,3,0),0) | U8: =+IFERROR(VLOOKUP($A8,[19]Balans!$A$5:$E$1048576,3,0),0) | V8: =+IFERROR(VLOOKUP($A8,'[20]1'!$A$5:$E$1048576,3,0),0) | W8: =+IFERROR(VLOOKUP($A8,[21]Balance!$A$5:$E$1048576,3,0),0) | X8: =+IFERROR(VLOOKUP($A8,'[22]1'!$A$5:$E$1048576,3,0),0) | Y8: =+IFERROR(VLOOKUP($A8,[23]Лист1!$A$5:$E$1048576,3,0),0) | Z8: =+IFERROR(VLOOKUP($A8,'[24]1'!$A$5:$E$1048576,3,0),0) | AA8: =+IFERROR(VLOOKUP($A8,[25]Balance!$A$5:$E$1048576,3,0),0) | AB8: =+IFERROR(VLOOKUP($A8,'[26]1'!$A$5:$E$1048576,3,0),0) | AC8: =+IFERROR(VLOOKUP($A8,'[27]1'!$A$5:$E$1048576,3,0),0) | AD8: =+IFERROR(VLOOKUP($A8,'[28]1'!$A$5:$E$1048576,3,0),0) | AE8: =+IFERROR(VLOOKUP($A8,[29]Лист1!$A$5:$E$1048576,3,0),0) | AF8: =+IFERROR(VLOOKUP($A8,'[30]1'!$A$5:$E$1048576,3,0),0) | AG8: =+IFERROR(VLOOKUP($A8,'[31]1'!$A$5:$E$1048576,3,0),0) | AH8: =+IFERROR(VLOOKUP($A8,'[32]1-жадвал'!$A$5:$E$1048576,3,0),0) | AI8: =+IFERROR(VLOOKUP($A8,[33]Balance!$A$5:$E$1048576,3,0),0) | AJ8: =+IFERROR(VLOOKUP($A8,[34]Balance!$A$5:$E$1048576,3,0),0) | AK8: =+IFERROR(VLOOKUP($A8,'[35]1'!$A$5:$E$1048576,3,0),0)
A9: 3.2 | B9: Минус: Кўрилиши мумкин бўлган зарарларни қоплаш захираси | C9: =+IFERROR(VLOOKUP($A9,[1]Лист1!$A$5:$E$1048576,3,0),0) | D9: =+IFERROR(VLOOKUP($A9,'[2]1'!$A$5:$E$1048576,3,0),0) | E9: =+IFERROR(VLOOKUP($A9,'[3]1'!$A$5:$E$1048576,3,0),0) | F9: =+IFERROR(VLOOKUP($A9,[4]Balance!$A$5:$E$1048576,3,0),0) | G9: =+IFERROR(VLOOKUP($A9,'[5]1'!$A$5:$E$1048576,3,0),0) | H9: =+IFERROR(VLOOKUP($A9,[6]Balance!$A$5:$E$1048576,3,0),0) | I9: =+IFERROR(VLOOKUP($A9,[7]Balance!$A$5:$E$1048576,3,0),0) | J9: =+IFERROR(VLOOKUP($A9,'[8]1'!$A$5:$E$1048576,3,0),0) | K9: =+IFERROR(VLOOKUP($A9,'[9]1'!$A$5:$E$1048576,3,0),0) | L9: =+IFERROR(VLOOKUP($A9,'[10]1'!$A$5:$E$1048576,3,0),0) | M9: =+IFERROR(VLOOKUP($A9,'[11]1'!$A$5:$E$1048576,3,0),0) | N9: =+IFERROR(VLOOKUP($A9,[12]Balance!$A$5:$E$1048576,3,0),0) | O9: =+IFERROR(VLOOKUP($A9,'[13]1 т'!$A$5:$E$1048576,3,0),0) | P9: =+IFERROR(VLOOKUP($A9,[14]Balance!$A$5:$E$1048576,3,0),0) | Q9: =+IFERROR(VLOOKUP($A9,[15]Balance!$A$5:$E$1048576,3,0),0) | R9: =+IFERROR(VLOOKUP($A9,'[16]1'!$A$5:$E$1048576,3,0),0) | S9: =+IFERROR(VLOOKUP($A9,'[17]1'!$A$5:$E$1048576,3,0),0) | T9: =+IFERROR(VLOOKUP($A9,'[18]1'!$A$5:$E$1048576,3,0),0) | U9: =+IFERROR(VLOOKUP($A9,[19]Balans!$A$5:$E$1048576,3,0),0) | V9: =+IFERROR(VLOOKUP($A9,'[20]1'!$A$5:$E$1048576,3,0),0) | W9: =+IFERROR(VLOOKUP($A9,[21]Balance!$A$5:$E$1048576,3,0),0) | X9: =+IFERROR(VLOOKUP($A9,'[22]1'!$A$5:$E$1048576,3,0),0) | Y9: =+IFERROR(VLOOKUP($A9,[23]Лист1!$A$5:$E$1048576,3,0),0) | Z9: =+IFERROR(VLOOKUP($A9,'[24]1'!$A$5:$E$1048576,3,0),0) | AA9: =+IFERROR(VLOOKUP($A9,[25]Balance!$A$5:$E$1048576,3,0),0) | AB9: =+IFERROR(VLOOKUP($A9,'[26]1'!$A$5:$E$1048576,3,0),0) | AC9: =+IFERROR(VLOOKUP($A9,'[27]1'!$A$5:$E$1048576,3,0),0) | AD9: =+IFERROR(VLOOKUP($A9,'[28]1'!$A$5:$E$1048576,3,0),0) | AE9: =+IFERROR(VLOOKUP($A9,[29]Лист1!$A$5:$E$1048576,3,0),0) | AF9: =+IFERROR(VLOOKUP($A9,'[30]1'!$A$5:$E$1048576,3,0),0) | AG9: =+IFERROR(VLOOKUP($A9,'[31]1'!$A$5:$E$1048576,3,0),0) | AH9: =+IFERROR(VLOOKUP($A9,'[32]1-жадвал'!$A$5:$E$1048576,3,0),0) | AI9: =+IFERROR(VLOOKUP($A9,[33]Balance!$A$5:$E$1048576,3,0),0) | AJ9: =+IFERROR(VLOOKUP($A9,[34]Balance!$A$5:$E$1048576,3,0),0) | AK9: =+IFERROR(VLOOKUP($A9,'[35]1'!$A$5:$E$1048576,3,0),0)
A10: 4 | B10: Қимматли қоғозлар ва уларга қилинган инвестициялар, соф | C10: =+IFERROR(VLOOKUP($A10,[1]Лист1!$A$5:$E$1048576,3,0),0) | D10: =+IFERROR(VLOOKUP($A10,'[2]1'!$A$5:$E$1048576,3,0),0) | E10: =+IFERROR(VLOOKUP($A10,'[3]1'!$A$5:$E$1048576,3,0),0) | F10: =+IFERROR(VLOOKUP($A10,[4]Balance!$A$5:$E$1048576,3,0),0) | G10: =+IFERROR(VLOOKUP($A10,'[5]1'!$A$5:$E$1048576,3,0),0) | H10: =+IFERROR(VLOOKUP($A10,[6]Balance!$A$5:$E$1048576,3,0),0) | I10: =+IFERROR(VLOOKUP($A10,[7]Balance!$A$5:$E$1048576,3,0),0) | J10: =+IFERROR(VLOOKUP($A10,'[8]1'!$A$5:$E$1048576,3,0),0) | K10: =+IFERROR(VLOOKUP($A10,'[9]1'!$A$5:$E$1048576,3,0),0) | L10: =+IFERROR(VLOOKUP($A10,'[10]1'!$A$5:$E$1048576,3,0),0) | M10: =+IFERROR(VLOOKUP($A10,'[11]1'!$A$5:$E$1048576,3,0),0) | N10: =+IFERROR(VLOOKUP($A10,[12]Balance!$A$5:$E$1048576,3,0),0) | O10: =+IFERROR(VLOOKUP($A10,'[13]1 т'!$A$5:$E$1048576,3,0),0) | P10: =+IFERROR(VLOOKUP($A10,[14]Balance!$A$5:$E$1048576,3,0),0) | Q10: =+IFERROR(VLOOKUP($A10,[15]Balance!$A$5:$E$1048576,3,0),0) | R10: =+IFERROR(VLOOKUP($A10,'[16]1'!$A$5:$E$1048576,3,0),0) | S10: =+IFERROR(VLOOKUP($A10,'[17]1'!$A$5:$E$1048576,3,0),0) | T10: =+IFERROR(VLOOKUP($A10,'[18]1'!$A$5:$E$1048576,3,0),0) | U10: =+IFERROR(VLOOKUP($A10,[19]Balans!$A$5:$E$1048576,3,0),0) | V10: =+IFERROR(VLOOKUP($A10,'[20]1'!$A$5:$E$1048576,3,0),0) | W10: =+IFERROR(VLOOKUP($A10,[21]Balance!$A$5:$E$1048576,3,0),0) | X10: =+IFERROR(VLOOKUP($A10,'[22]1'!$A$5:$E$1048576,3,0),0) | Y10: =+IFERROR(VLOOKUP($A10,[23]Лист1!$A$5:$E$1048576,3,0),0) | Z10: =+IFERROR(VLOOKUP($A10,'[24]1'!$A$5:$E$1048576,3,0),0) | AA10: =+IFERROR(VLOOKUP($A10,[25]Balance!$A$5:$E$1048576,3,0),0) | AB10: =+IFERROR(VLOOKUP($A10,'[26]1'!$A$5:$E$1048576,3,0),0) | AC10: =+IFERROR(VLOOKUP($A10,'[27]1'!$A$5:$E$1048576,3,0),0) | AD10: =+IFERROR(VLOOKUP($A10,'[28]1'!$A$5:$E$1048576,3,0),0) | AE10: =+IFERROR(VLOOKUP($A10,[29]Лист1!$A$5:$E$1048576,3,0),0) | AF10: =+IFERROR(VLOOKUP($A10,'[30]1'!$A$5:$E$1048576,3,0),0) | AG10: =+IFERROR(VLOOKUP($A10,'[31]1'!$A$5:$E$1048576,3,0),0) | AH10: =+IFERROR(VLOOKUP($A10,'[32]1-жадвал'!$A$5:$E$1048576,3,0),0) | AI10: =+IFERROR(VLOOKUP($A10,[33]Balance!$A$5:$E$1048576,3,0),0) | AJ10: =+IFERROR(VLOOKUP($A10,[34]Balance!$A$5:$E$1048576,3,0),0) | AK10: =+IFERROR(VLOOKUP($A10,'[35]1'!$A$5:$E$1048576,3,0),0)
A11: 4.1 | B11: Қимматли қоғозлар ва уларга қилинган инвестициялар, брутто | C11: =+IFERROR(VLOOKUP($A11,[1]Лист1!$A$5:$E$1048576,3,0),0) | D11: =+IFERROR(VLOOKUP($A11,'[2]1'!$A$5:$E$1048576,3,0),0) | E11: =+IFERROR(VLOOKUP($A11,'[3]1'!$A$5:$E$1048576,3,0),0) | F11: =+IFERROR(VLOOKUP($A11,[4]Balance!$A$5:$E$1048576,3,0),0) | G11: =+IFERROR(VLOOKUP($A11,'[5]1'!$A$5:$E$1048576,3,0),0) | H11: =+IFERROR(VLOOKUP($A11,[6]Balance!$A$5:$E$1048576,3,0),0) | I11: =+IFERROR(VLOOKUP($A11,[7]Balance!$A$5:$E$1048576,3,0),0) | J11: =+IFERROR(VLOOKUP($A11,'[8]1'!$A$5:$E$1048576,3,0),0) | K11: =+IFERROR(VLOOKUP($A11,'[9]1'!$A$5:$E$1048576,3,0),0) | L11: =+IFERROR(VLOOKUP($A11,'[10]1'!$A$5:$E$1048576,3,0),0) | M11: =+IFERROR(VLOOKUP($A11,'[11]1'!$A$5:$E$1048576,3,0),0) | N11: =+IFERROR(VLOOKUP($A11,[12]Balance!$A$5:$E$1048576,3,0),0) | O11: =+IFERROR(VLOOKUP($A11,'[13]1 т'!$A$5:$E$1048576,3,0),0) | P11: =+IFERROR(VLOOKUP($A11,[14]Balance!$A$5:$E$1048576,3,0),0) | Q11: =+IFERROR(VLOOKUP($A11,[15]Balance!$A$5:$E$1048576,3,0),0) | R11: =+IFERROR(VLOOKUP($A11,'[16]1'!$A$5:$E$1048576,3,0),0) | S11: =+IFERROR(VLOOKUP($A11,'[17]1'!$A$5:$E$1048576,3,0),0) | T11: =+IFERROR(VLOOKUP($A11,'[18]1'!$A$5:$E$1048576,3,0),0) | U11: =+IFERROR(VLOOKUP($A11,[19]Balans!$A$5:$E$1048576,3,0),0) | V11: =+IFERROR(VLOOKUP($A11,'[20]1'!$A$5:$E$1048576,3,0),0) | W11: =+IFERROR(VLOOKUP($A11,[21]Balance!$A$5:$E$1048576,3,0),0) | X11: =+IFERROR(VLOOKUP($A11,'[22]1'!$A$5:$E$1048576,3,0),0) | Y11: =+IFERROR(VLOOKUP($A11,[23]Лист1!$A$5:$E$1048576,3,0),0) | Z11: =+IFERROR(VLOOKUP($A11,'[24]1'!$A$5:$E$1048576,3,0),0) | AA11: =+IFERROR(VLOOKUP($A11,[25]Balance!$A$5:$E$1048576,3,0),0) | AB11: =+IFERROR(VLOOKUP($A11,'[26]1'!$A$5:$E$1048576,3,0),0) | AC11: =+IFERROR(VLOOKUP($A11,'[27]1'!$A$5:$E$1048576,3,0),0) | AD11: =+IFERROR(VLOOKUP($A11,'[28]1'!$A$5:$E$1048576,3,0),0) | AE11: =+IFERROR(VLOOKUP($A11,[29]Лист1!$A$5:$E$1048576,3,0),0) | AF11: =+IFERROR(VLOOKUP($A11,'[30]1'!$A$5:$E$1048576,3,0),0) | AG11: =+IFERROR(VLOOKUP($A11,'[31]1'!$A$5:$E$1048576,3,0),0) | AH11: =+IFERROR(VLOOKUP($A11,'[32]1-жадвал'!$A$5:$E$1048576,3,0),0) | AI11: =+IFERROR(VLOOKUP($A11,[33]Balance!$A$5:$E$1048576,3,0),0) | AJ11: =+IFERROR(VLOOKUP($A11,[34]Balance!$A$5:$E$1048576,3,0),0) | AK11: =+IFERROR(VLOOKUP($A11,'[35]1'!$A$5:$E$1048576,3,0),0)
A12: 4.2 | B12: Қимматли қоғозлар бўйича харажатлар, дисконт, мукофот ва уларнинг ҳаққоний қийматининг ўзгариши | C12: =+IFERROR(VLOOKUP($A12,[1]Лист1!$A$5:$E$1048576,3,0),0) | D12: =+IFERROR(VLOOKUP($A12,'[2]1'!$A$5:$E$1048576,3,0),0) | E12: =+IFERROR(VLOOKUP($A12,'[3]1'!$A$5:$E$1048576,3,0),0) | F12: =+IFERROR(VLOOKUP($A12,[4]Balance!$A$5:$E$1048576,3,0),0) | G12: =+IFERROR(VLOOKUP($A12,'[5]1'!$A$5:$E$1048576,3,0),0) | H12: =+IFERROR(VLOOKUP($A12,[6]Balance!$A$5:$E$1048576,3,0),0) | I12: =+IFERROR(VLOOKUP($A12,[7]Balance!$A$5:$E$1048576,3,0),0) | J12: =+IFERROR(VLOOKUP($A12,'[8]1'!$A$5:$E$1048576,3,0),0) | K12: =+IFERROR(VLOOKUP($A12,'[9]1'!$A$5:$E$1048576,3,0),0) | L12: =+IFERROR(VLOOKUP($A12,'[10]1'!$A$5:$E$1048576,3,0),0) | M12: =+IFERROR(VLOOKUP($A12,'[11]1'!$A$5:$E$1048576,3,0),0) | N12: =+IFERROR(VLOOKUP($A12,[12]Balance!$A$5:$E$1048576,3,0),0) | O12: =+IFERROR(VLOOKUP($A12,'[13]1 т'!$A$5:$E$1048576,3,0),0) | P12: =+IFERROR(VLOOKUP($A12,[14]Balance!$A$5:$E$1048576,3,0),0) | Q12: =+IFERROR(VLOOKUP($A12,[15]Balance!$A$5:$E$1048576,3,0),0) | R12: =+IFERROR(VLOOKUP($A12,'[16]1'!$A$5:$E$1048576,3,0),0) | S12: =+IFERROR(VLOOKUP($A12,'[17]1'!$A$5:$E$1048576,3,0),0) | T12: =+IFERROR(VLOOKUP($A12,'[18]1'!$A$5:$E$1048576,3,0),0) | U12: =+IFERROR(VLOOKUP($A12,[19]Balans!$A$5:$E$1048576,3,0),0) | V12: =+IFERROR(VLOOKUP($A12,'[20]1'!$A$5:$E$1048576,3,0),0) | W12: =+IFERROR(VLOOKUP($A12,[21]Balance!$A$5:$E$1048576,3,0),0) | X12: =+IFERROR(VLOOKUP($A12,'[22]1'!$A$5:$E$1048576,3,0),0) | Y12: =+IFERROR(VLOOKUP($A12,[23]Лист1!$A$5:$E$1048576,3,0),0) | Z12: =+IFERROR(VLOOKUP($A12,'[24]1'!$A$5:$E$1048576,3,0),0) | AA12: =+IFERROR(VLOOKUP($A12,[25]Balance!$A$5:$E$1048576,3,0),0) | AB12: =+IFERROR(VLOOKUP($A12,'[26]1'!$A$5:$E$1048576,3,0),0) | AC12: =+IFERROR(VLOOKUP($A12,'[27]1'!$A$5:$E$1048576,3,0),0) | AD12: =+IFERROR(VLOOKUP($A12,'[28]1'!$A$5:$E$1048576,3,0),0) | AE12: =+IFERROR(VLOOKUP($A12,[29]Лист1!$A$5:$E$1048576,3,0),0) | AF12: =+IFERROR(VLOOKUP($A12,'[30]1'!$A$5:$E$1048576,3,0),0) | AG12: =+IFERROR(VLOOKUP($A12,'[31]1'!$A$5:$E$1048576,3,0),0) | AH12: =+IFERROR(VLOOKUP($A12,'[32]1-жадвал'!$A$5:$E$1048576,3,0),0) | AI12: =+IFERROR(VLOOKUP($A12,[33]Balance!$A$5:$E$1048576,3,0),0) | AJ12: =+IFERROR(VLOOKUP($A12,[34]Balance!$A$5:$E$1048576,3,0),0) | AK12: =+IFERROR(VLOOKUP($A12,'[35]1'!$A$5:$E$1048576,3,0),0)
A13: 4.3 | B13: Минус: Кўрилиши мумкин бўлган зарарларни қоплаш захираси | C13: =+IFERROR(VLOOKUP($A13,[1]Лист1!$A$5:$E$1048576,3,0),0) | D13: =+IFERROR(VLOOKUP($A13,'[2]1'!$A$5:$E$1048576,3,0),0) | E13: =+IFERROR(VLOOKUP($A13,'[3]1'!$A$5:$E$1048576,3,0),0) | F13: =+IFERROR(VLOOKUP($A13,[4]Balance!$A$5:$E$1048576,3,0),0) | G13: =+IFERROR(VLOOKUP($A13,'[5]1'!$A$5:$E$1048576,3,0),0) | H13: =+IFERROR(VLOOKUP($A13,[6]Balance!$A$5:$E$1048576,3,0),0) | I13: =+IFERROR(VLOOKUP($A13,[7]Balance!$A$5:$E$1048576,3,0),0) | J13: =+IFERROR(VLOOKUP($A13,'[8]1'!$A$5:$E$1048576,3,0),0) | K13: =+IFERROR(VLOOKUP($A13,'[9]1'!$A$5:$E$1048576,3,0),0) | L13: =+IFERROR(VLOOKUP($A13,'[10]1'!$A$5:$E$1048576,3,0),0) | M13: =+IFERROR(VLOOKUP($A13,'[11]1'!$A$5:$E$1048576,3,0),0) | N13: =+IFERROR(VLOOKUP($A13,[12]Balance!$A$5:$E$1048576,3,0),0) | O13: =+IFERROR(VLOOKUP($A13,'[13]1 т'!$A$5:$E$1048576,3,0),0) | P13: =+IFERROR(VLOOKUP($A13,[14]Balance!$A$5:$E$1048576,3,0),0) | Q13: =+IFERROR(VLOOKUP($A13,[15]Balance!$A$5:$E$1048576,3,0),0) | R13: =+IFERROR(VLOOKUP($A13,'[16]1'!$A$5:$E$1048576,3,0),0) | S13: =+IFERROR(VLOOKUP($A13,'[17]1'!$A$5:$E$1048576,3,0),0) | T13: =+IFERROR(VLOOKUP($A13,'[18]1'!$A$5:$E$1048576,3,0),0) | U13: =+IFERROR(VLOOKUP($A13,[19]Balans!$A$5:$E$1048576,3,0),0) | V13: =+IFERROR(VLOOKUP($A13,'[20]1'!$A$5:$E$1048576,3,0),0) | W13: =+IFERROR(VLOOKUP($A13,[21]Balance!$A$5:$E$1048576,3,0),0) | X13: =+IFERROR(VLOOKUP($A13,'[22]1'!$A$5:$E$1048576,3,0),0) | Y13: =+IFERROR(VLOOKUP($A13,[23]Лист1!$A$5:$E$1048576,3,0),0) | Z13: =+IFERROR(VLOOKUP($A13,'[24]1'!$A$5:$E$1048576,3,0),0) | AA13: =+IFERROR(VLOOKUP($A13,[25]Balance!$A$5:$E$1048576,3,0),0) | AB13: =+IFERROR(VLOOKUP($A13,'[26]1'!$A$5:$E$1048576,3,0),0) | AC13: =+IFERROR(VLOOKUP($A13,'[27]1'!$A$5:$E$1048576,3,0),0) | AD13: =+IFERROR(VLOOKUP($A13,'[28]1'!$A$5:$E$1048576,3,0),0) | AE13: =+IFERROR(VLOOKUP($A13,[29]Лист1!$A$5:$E$1048576,3,0),0) | AF13: =+IFERROR(VLOOKUP($A13,'[30]1'!$A$5:$E$1048576,3,0),0) | AG13: =+IFERROR(VLOOKUP($A13,'[31]1'!$A$5:$E$1048576,3,0),0) | AH13: =+IFERROR(VLOOKUP($A13,'[32]1-жадвал'!$A$5:$E$1048576,3,0),0) | AI13: =+IFERROR(VLOOKUP($A13,[33]Balance!$A$5:$E$1048576,3,0),0) | AJ13: =+IFERROR(VLOOKUP($A13,[34]Balance!$A$5:$E$1048576,3,0),0) | AK13: =+IFERROR(VLOOKUP($A13,'[35]1'!$A$5:$E$1048576,3,0),0)
A14: 5 | B14: Қимматбаҳо металлар, тошлар ва тангалар, соф | C14: =+IFERROR(VLOOKUP($A14,[1]Лист1!$A$5:$E$1048576,3,0),0) | D14: =+IFERROR(VLOOKUP($A14,'[2]1'!$A$5:$E$1048576,3,0),0) | E14: =+IFERROR(VLOOKUP($A14,'[3]1'!$A$5:$E$1048576,3,0),0) | F14: =+IFERROR(VLOOKUP($A14,[4]Balance!$A$5:$E$1048576,3,0),0) | G14: =+IFERROR(VLOOKUP($A14,'[5]1'!$A$5:$E$1048576,3,0),0) | H14: =+IFERROR(VLOOKUP($A14,[6]Balance!$A$5:$E$1048576,3,0),0) | I14: =+IFERROR(VLOOKUP($A14,[7]Balance!$A$5:$E$1048576,3,0),0) | J14: =+IFERROR(VLOOKUP($A14,'[8]1'!$A$5:$E$1048576,3,0),0) | K14: =+IFERROR(VLOOKUP($A14,'[9]1'!$A$5:$E$1048576,3,0),0) | L14: =+IFERROR(VLOOKUP($A14,'[10]1'!$A$5:$E$1048576,3,0),0) | M14: =+IFERROR(VLOOKUP($A14,'[11]1'!$A$5:$E$1048576,3,0),0) | N14: =+IFERROR(VLOOKUP($A14,[12]Balance!$A$5:$E$1048576,3,0),0) | O14: =+IFERROR(VLOOKUP($A14,'[13]1 т'!$A$5:$E$1048576,3,0),0) | P14: =+IFERROR(VLOOKUP($A14,[14]Balance!$A$5:$E$1048576,3,0),0) | Q14: =+IFERROR(VLOOKUP($A14,[15]Balance!$A$5:$E$1048576,3,0),0) | R14: =+IFERROR(VLOOKUP($A14,'[16]1'!$A$5:$E$1048576,3,0),0) | S14: =+IFERROR(VLOOKUP($A14,'[17]1'!$A$5:$E$1048576,3,0),0) | T14: =+IFERROR(VLOOKUP($A14,'[18]1'!$A$5:$E$1048576,3,0),0) | U14: =+IFERROR(VLOOKUP($A14,[19]Balans!$A$5:$E$1048576,3,0),0) | V14: =+IFERROR(VLOOKUP($A14,'[20]1'!$A$5:$E$1048576,3,0),0) | W14: =+IFERROR(VLOOKUP($A14,[21]Balance!$A$5:$E$1048576,3,0),0) | X14: =+IFERROR(VLOOKUP($A14,'[22]1'!$A$5:$E$1048576,3,0),0) | Y14: =+IFERROR(VLOOKUP($A14,[23]Лист1!$A$5:$E$1048576,3,0),0) | Z14: =+IFERROR(VLOOKUP($A14,'[24]1'!$A$5:$E$1048576,3,0),0) | AA14: =+IFERROR(VLOOKUP($A14,[25]Balance!$A$5:$E$1048576,3,0),0) | AB14: =+IFERROR(VLOOKUP($A14,'[26]1'!$A$5:$E$1048576,3,0),0) | AC14: =+IFERROR(VLOOKUP($A14,'[27]1'!$A$5:$E$1048576,3,0),0) | AD14: =+IFERROR(VLOOKUP($A14,'[28]1'!$A$5:$E$1048576,3,0),0) | AE14: =+IFERROR(VLOOKUP($A14,[29]Лист1!$A$5:$E$1048576,3,0),0) | AF14: =+IFERROR(VLOOKUP($A14,'[30]1'!$A$5:$E$1048576,3,0),0) | AG14: =+IFERROR(VLOOKUP($A14,'[31]1'!$A$5:$E$1048576,3,0),0) | AH14: =+IFERROR(VLOOKUP($A14,'[32]1-жадвал'!$A$5:$E$1048576,3,0),0) | AI14: =+IFERROR(VLOOKUP($A14,[33]Balance!$A$5:$E$1048576,3,0),0) | AJ14: =+IFERROR(VLOOKUP($A14,[34]Balance!$A$5:$E$1048576,3,0),0) | AK14: =+IFERROR(VLOOKUP($A14,'[35]1'!$A$5:$E$1048576,3,0),0)
A15: 5.1 | B15: Қимматбаҳо металлар, тошлар ва тангалар, брутто | C15: =+IFERROR(VLOOKUP($A15,[1]Лист1!$A$5:$E$1048576,3,0),0) | D15: =+IFERROR(VLOOKUP($A15,'[2]1'!$A$5:$E$1048576,3,0),0) | E15: =+IFERROR(VLOOKUP($A15,'[3]1'!$A$5:$E$1048576,3,0),0) | F15: =+IFERROR(VLOOKUP($A15,[4]Balance!$A$5:$E$1048576,3,0),0) | G15: =+IFERROR(VLOOKUP($A15,'[5]1'!$A$5:$E$1048576,3,0),0) | H15: =+IFERROR(VLOOKUP($A15,[6]Balance!$A$5:$E$1048576,3,0),0) | I15: =+IFERROR(VLOOKUP($A15,[7]Balance!$A$5:$E$1048576,3,0),0) | J15: =+IFERROR(VLOOKUP($A15,'[8]1'!$A$5:$E$1048576,3,0),0) | K15: =+IFERROR(VLOOKUP($A15,'[9]1'!$A$5:$E$1048576,3,0),0) | L15: =+IFERROR(VLOOKUP($A15,'[10]1'!$A$5:$E$1048576,3,0),0) | M15: =+IFERROR(VLOOKUP($A15,'[11]1'!$A$5:$E$1048576,3,0),0) | N15: =+IFERROR(VLOOKUP($A15,[12]Balance!$A$5:$E$1048576,3,0),0) | O15: =+IFERROR(VLOOKUP($A15,'[13]1 т'!$A$5:$E$1048576,3,0),0) | P15: =+IFERROR(VLOOKUP($A15,[14]Balance!$A$5:$E$1048576,3,0),0) | Q15: =+IFERROR(VLOOKUP($A15,[15]Balance!$A$5:$E$1048576,3,0),0) | R15: =+IFERROR(VLOOKUP($A15,'[16]1'!$A$5:$E$1048576,3,0),0) | S15: =+IFERROR(VLOOKUP($A15,'[17]1'!$A$5:$E$1048576,3,0),0) | T15: =+IFERROR(VLOOKUP($A15,'[18]1'!$A$5:$E$1048576,3,0),0) | U15: =+IFERROR(VLOOKUP($A15,[19]Balans!$A$5:$E$1048576,3,0),0) | V15: =+IFERROR(VLOOKUP($A15,'[20]1'!$A$5:$E$1048576,3,0),0) | W15: =+IFERROR(VLOOKUP($A15,[21]Balance!$A$5:$E$1048576,3,0),0) | X15: =+IFERROR(VLOOKUP($A15,'[22]1'!$A$5:$E$1048576,3,0),0) | Y15: =+IFERROR(VLOOKUP($A15,[23]Лист1!$A$5:$E$1048576,3,0),0) | Z15: =+IFERROR(VLOOKUP($A15,'[24]1'!$A$5:$E$1048576,3,0),0) | AA15: =+IFERROR(VLOOKUP($A15,[25]Balance!$A$5:$E$1048576,3,0),0) | AB15: =+IFERROR(VLOOKUP($A15,'[26]1'!$A$5:$E$1048576,3,0),0) | AC15: =+IFERROR(VLOOKUP($A15,'[27]1'!$A$5:$E$1048576,3,0),0) | AD15: =+IFERROR(VLOOKUP($A15,'[28]1'!$A$5:$E$1048576,3,0),0) | AE15: =+IFERROR(VLOOKUP($A15,[29]Лист1!$A$5:$E$1048576,3,0),0) | AF15: =+IFERROR(VLOOKUP($A15,'[30]1'!$A$5:$E$1048576,3,0),0) | AG15: =+IFERROR(VLOOKUP($A15,'[31]1'!$A$5:$E$1048576,3,0),0) | AH15: =+IFERROR(VLOOKUP($A15,'[32]1-жадвал'!$A$5:$E$1048576,3,0),0) | AI15: =+IFERROR(VLOOKUP($A15,[33]Balance!$A$5:$E$1048576,3,0),0) | AJ15: =+IFERROR(VLOOKUP($A15,[34]Balance!$A$5:$E$1048576,3,0),0) | AK15: =+IFERROR(VLOOKUP($A15,'[35]1'!$A$5:$E$1048576,3,0),0)
A16: 5.2 | B16: Минус: Кўрилиши мумкин бўлган зарарларни қоплаш захираси | C16: =+IFERROR(VLOOKUP($A16,[1]Лист1!$A$5:$E$1048576,3,0),0) | D16: =+IFERROR(VLOOKUP($A16,'[2]1'!$A$5:$E$1048576,3,0),0) | E16: =+IFERROR(VLOOKUP($A16,'[3]1'!$A$5:$E$1048576,3,0),0) | F16: =+IFERROR(VLOOKUP($A16,[4]Balance!$A$5:$E$1048576,3,0),0) | G16: =+IFERROR(VLOOKUP($A16,'[5]1'!$A$5:$E$1048576,3,0),0) | H16: =+IFERROR(VLOOKUP($A16,[6]Balance!$A$5:$E$1048576,3,0),0) | I16: =+IFERROR(VLOOKUP($A16,[7]Balance!$A$5:$E$1048576,3,0),0) | J16: =+IFERROR(VLOOKUP($A16,'[8]1'!$A$5:$E$1048576,3,0),0) | K16: =+IFERROR(VLOOKUP($A16,'[9]1'!$A$5:$E$1048576,3,0),0) | L16: =+IFERROR(VLOOKUP($A16,'[10]1'!$A$5:$E$1048576,3,0),0) | M16: =+IFERROR(VLOOKUP($A16,'[11]1'!$A$5:$E$1048576,3,0),0) | N16: =+IFERROR(VLOOKUP($A16,[12]Balance!$A$5:$E$1048576,3,0),0) | O16: =+IFERROR(VLOOKUP($A16,'[13]1 т'!$A$5:$E$1048576,3,0),0) | P16: =+IFERROR(VLOOKUP($A16,[14]Balance!$A$5:$E$1048576,3,0),0) | Q16: =+IFERROR(VLOOKUP($A16,[15]Balance!$A$5:$E$1048576,3,0),0) | R16: =+IFERROR(VLOOKUP($A16,'[16]1'!$A$5:$E$1048576,3,0),0) | S16: =+IFERROR(VLOOKUP($A16,'[17]1'!$A$5:$E$1048576,3,0),0) | T16: =+IFERROR(VLOOKUP($A16,'[18]1'!$A$5:$E$1048576,3,0),0) | U16: =+IFERROR(VLOOKUP($A16,[19]Balans!$A$5:$E$1048576,3,0),0) | V16: =+IFERROR(VLOOKUP($A16,'[20]1'!$A$5:$E$1048576,3,0),0) | W16: =+IFERROR(VLOOKUP($A16,[21]Balance!$A$5:$E$1048576,3,0),0) | X16: =+IFERROR(VLOOKUP($A16,'[22]1'!$A$5:$E$1048576,3,0),0) | Y16: =+IFERROR(VLOOKUP($A16,[23]Лист1!$A$5:$E$1048576,3,0),0) | Z16: =+IFERROR(VLOOKUP($A16,'[24]1'!$A$5:$E$1048576,3,0),0) | AA16: =+IFERROR(VLOOKUP($A16,[25]Balance!$A$5:$E$1048576,3,0),0) | AB16: =+IFERROR(VLOOKUP($A16,'[26]1'!$A$5:$E$1048576,3,0),0) | AC16: =+IFERROR(VLOOKUP($A16,'[27]1'!$A$5:$E$1048576,3,0),0) | AD16: =+IFERROR(VLOOKUP($A16,'[28]1'!$A$5:$E$1048576,3,0),0) | AE16: =+IFERROR(VLOOKUP($A16,[29]Лист1!$A$5:$E$1048576,3,0),0) | AF16: =+IFERROR(VLOOKUP($A16,'[30]1'!$A$5:$E$1048576,3,0),0) | AG16: =+IFERROR(VLOOKUP($A16,'[31]1'!$A$5:$E$1048576,3,0),0) | AH16: =+IFERROR(VLOOKUP($A16,'[32]1-жадвал'!$A$5:$E$1048576,3,0),0) | AI16: =+IFERROR(VLOOKUP($A16,[33]Balance!$A$5:$E$1048576,3,0),0) | AJ16: =+IFERROR(VLOOKUP($A16,[34]Balance!$A$5:$E$1048576,3,0),0) | AK16: =+IFERROR(VLOOKUP($A16,'[35]1'!$A$5:$E$1048576,3,0),0)
A17: 6 | B17: Инвестициялар, соф | C17: =+IFERROR(VLOOKUP($A17,[1]Лист1!$A$5:$E$1048576,3,0),0) | D17: =+IFERROR(VLOOKUP($A17,'[2]1'!$A$5:$E$1048576,3,0),0) | E17: =+IFERROR(VLOOKUP($A17,'[3]1'!$A$5:$E$1048576,3,0),0) | F17: =+IFERROR(VLOOKUP($A17,[4]Balance!$A$5:$E$1048576,3,0),0) | G17: =+IFERROR(VLOOKUP($A17,'[5]1'!$A$5:$E$1048576,3,0),0) | H17: =+IFERROR(VLOOKUP($A17,[6]Balance!$A$5:$E$1048576,3,0),0) | I17: =+IFERROR(VLOOKUP($A17,[7]Balance!$A$5:$E$1048576,3,0),0) | J17: =+IFERROR(VLOOKUP($A17,'[8]1'!$A$5:$E$1048576,3,0),0) | K17: =+IFERROR(VLOOKUP($A17,'[9]1'!$A$5:$E$1048576,3,0),0) | L17: =+IFERROR(VLOOKUP($A17,'[10]1'!$A$5:$E$1048576,3,0),0) | M17: =+IFERROR(VLOOKUP($A17,'[11]1'!$A$5:$E$1048576,3,0),0) | N17: =+IFERROR(VLOOKUP($A17,[12]Balance!$A$5:$E$1048576,3,0),0) | O17: =+IFERROR(VLOOKUP($A17,'[13]1 т'!$A$5:$E$1048576,3,0),0) | P17: =+IFERROR(VLOOKUP($A17,[14]Balance!$A$5:$E$1048576,3,0),0) | Q17: =+IFERROR(VLOOKUP($A17,[15]Balance!$A$5:$E$1048576,3,0),0) | R17: =+IFERROR(VLOOKUP($A17,'[16]1'!$A$5:$E$1048576,3,0),0) | S17: =+IFERROR(VLOOKUP($A17,'[17]1'!$A$5:$E$1048576,3,0),0) | T17: =+IFERROR(VLOOKUP($A17,'[18]1'!$A$5:$E$1048576,3,0),0) | U17: =+IFERROR(VLOOKUP($A17,[19]Balans!$A$5:$E$1048576,3,0),0) | V17: =+IFERROR(VLOOKUP($A17,'[20]1'!$A$5:$E$1048576,3,0),0) | W17: =+IFERROR(VLOOKUP($A17,[21]Balance!$A$5:$E$1048576,3,0),0) | X17: =+IFERROR(VLOOKUP($A17,'[22]1'!$A$5:$E$1048576,3,0),0) | Y17: =+IFERROR(VLOOKUP($A17,[23]Лист1!$A$5:$E$1048576,3,0),0) | Z17: =+IFERROR(VLOOKUP($A17,'[24]1'!$A$5:$E$1048576,3,0),0) | AA17: =+IFERROR(VLOOKUP($A17,[25]Balance!$A$5:$E$1048576,3,0),0) | AB17: =+IFERROR(VLOOKUP($A17,'[26]1'!$A$5:$E$1048576,3,0),0) | AC17: =+IFERROR(VLOOKUP($A17,'[27]1'!$A$5:$E$1048576,3,0),0) | AD17: =+IFERROR(VLOOKUP($A17,'[28]1'!$A$5:$E$1048576,3,0),0) | AE17: =+IFERROR(VLOOKUP($A17,[29]Лист1!$A$5:$E$1048576,3,0),0) | AF17: =+IFERROR(VLOOKUP($A17,'[30]1'!$A$5:$E$1048576,3,0),0) | AG17: =+IFERROR(VLOOKUP($A17,'[31]1'!$A$5:$E$1048576,3,0),0) | AH17: =+IFERROR(VLOOKUP($A17,'[32]1-жадвал'!$A$5:$E$1048576,3,0),0) | AI17: =+IFERROR(VLOOKUP($A17,[33]Balance!$A$5:$E$1048576,3,0),0) | AJ17: =+IFERROR(VLOOKUP($A17,[34]Balance!$A$5:$E$1048576,3,0),0) | AK17: =+IFERROR(VLOOKUP($A17,'[35]1'!$A$5:$E$1048576,3,0),0)
A18: 6.1 | B18: Инвестициялар, брутто | C18: =+IFERROR(VLOOKUP($A18,[1]Лист1!$A$5:$E$1048576,3,0),0) | D18: =+IFERROR(VLOOKUP($A18,'[2]1'!$A$5:$E$1048576,3,0),0) | E18: =+IFERROR(VLOOKUP($A18,'[3]1'!$A$5:$E$1048576,3,0),0) | F18: =+IFERROR(VLOOKUP($A18,[4]Balance!$A$5:$E$1048576,3,0),0) | G18: =+IFERROR(VLOOKUP($A18,'[5]1'!$A$5:$E$1048576,3,0),0) | H18: =+IFERROR(VLOOKUP($A18,[6]Balance!$A$5:$E$1048576,3,0),0) | I18: =+IFERROR(VLOOKUP($A18,[7]Balance!$A$5:$E$1048576,3,0),0) | J18: =+IFERROR(VLOOKUP($A18,'[8]1'!$A$5:$E$1048576,3,0),0) | K18: =+IFERROR(VLOOKUP($A18,'[9]1'!$A$5:$E$1048576,3,0),0) | L18: =+IFERROR(VLOOKUP($A18,'[10]1'!$A$5:$E$1048576,3,0),0) | M18: =+IFERROR(VLOOKUP($A18,'[11]1'!$A$5:$E$1048576,3,0),0) | N18: =+IFERROR(VLOOKUP($A18,[12]Balance!$A$5:$E$1048576,3,0),0) | O18: =+IFERROR(VLOOKUP($A18,'[13]1 т'!$A$5:$E$1048576,3,0),0) | P18: =+IFERROR(VLOOKUP($A18,[14]Balance!$A$5:$E$1048576,3,0),0) | Q18: =+IFERROR(VLOOKUP($A18,[15]Balance!$A$5:$E$1048576,3,0),0) | R18: =+IFERROR(VLOOKUP($A18,'[16]1'!$A$5:$E$1048576,3,0),0) | S18: =+IFERROR(VLOOKUP($A18,'[17]1'!$A$5:$E$1048576,3,0),0) | T18: =+IFERROR(VLOOKUP($A18,'[18]1'!$A$5:$E$1048576,3,0),0) | U18: =+IFERROR(VLOOKUP($A18,[19]Balans!$A$5:$E$1048576,3,0),0) | V18: =+IFERROR(VLOOKUP($A18,'[20]1'!$A$5:$E$1048576,3,0),0) | W18: =+IFERROR(VLOOKUP($A18,[21]Balance!$A$5:$E$1048576,3,0),0) | X18: =+IFERROR(VLOOKUP($A18,'[22]1'!$A$5:$E$1048576,3,0),0) | Y18: =+IFERROR(VLOOKUP($A18,[23]Лист1!$A$5:$E$1048576,3,0),0) | Z18: =+IFERROR(VLOOKUP($A18,'[24]1'!$A$5:$E$1048576,3,0),0) | AA18: =+IFERROR(VLOOKUP($A18,[25]Balance!$A$5:$E$1048576,3,0),0) | AB18: =+IFERROR(VLOOKUP($A18,'[26]1'!$A$5:$E$1048576,3,0),0) | AC18: =+IFERROR(VLOOKUP($A18,'[27]1'!$A$5:$E$1048576,3,0),0) | AD18: =+IFERROR(VLOOKUP($A18,'[28]1'!$A$5:$E$1048576,3,0),0) | AE18: =+IFERROR(VLOOKUP($A18,[29]Лист1!$A$5:$E$1048576,3,0),0) | AF18: =+IFERROR(VLOOKUP($A18,'[30]1'!$A$5:$E$1048576,3,0),0) | AG18: =+IFERROR(VLOOKUP($A18,'[31]1'!$A$5:$E$1048576,3,0),0) | AH18: =+IFERROR(VLOOKUP($A18,'[32]1-жадвал'!$A$5:$E$1048576,3,0),0) | AI18: =+IFERROR(VLOOKUP($A18,[33]Balance!$A$5:$E$1048576,3,0),0) | AJ18: =+IFERROR(VLOOKUP($A18,[34]Balance!$A$5:$E$1048576,3,0),0) | AK18: =+IFERROR(VLOOKUP($A18,'[35]1'!$A$5:$E$1048576,3,0),0)
A19: 6.2 | B19: Инвестициялар бўйича харажатлар, дисконт ва мукофот | C19: =+IFERROR(VLOOKUP($A19,[1]Лист1!$A$5:$E$1048576,3,0),0) | D19: =+IFERROR(VLOOKUP($A19,'[2]1'!$A$5:$E$1048576,3,0),0) | E19: =+IFERROR(VLOOKUP($A19,'[3]1'!$A$5:$E$1048576,3,0),0) | F19: =+IFERROR(VLOOKUP($A19,[4]Balance!$A$5:$E$1048576,3,0),0) | G19: =+IFERROR(VLOOKUP($A19,'[5]1'!$A$5:$E$1048576,3,0),0) | H19: =+IFERROR(VLOOKUP($A19,[6]Balance!$A$5:$E$1048576,3,0),0) | I19: =+IFERROR(VLOOKUP($A19,[7]Balance!$A$5:$E$1048576,3,0),0) | J19: =+IFERROR(VLOOKUP($A19,'[8]1'!$A$5:$E$1048576,3,0),0) | K19: =+IFERROR(VLOOKUP($A19,'[9]1'!$A$5:$E$1048576,3,0),0) | L19: =+IFERROR(VLOOKUP($A19,'[10]1'!$A$5:$E$1048576,3,0),0) | M19: =+IFERROR(VLOOKUP($A19,'[11]1'!$A$5:$E$1048576,3,0),0) | N19: =+IFERROR(VLOOKUP($A19,[12]Balance!$A$5:$E$1048576,3,0),0) | O19: =+IFERROR(VLOOKUP($A19,'[13]1 т'!$A$5:$E$1048576,3,0),0) | P19: =+IFERROR(VLOOKUP($A19,[14]Balance!$A$5:$E$1048576,3,0),0) | Q19: =+IFERROR(VLOOKUP($A19,[15]Balance!$A$5:$E$1048576,3,0),0) | R19: =+IFERROR(VLOOKUP($A19,'[16]1'!$A$5:$E$1048576,3,0),0) | S19: =+IFERROR(VLOOKUP($A19,'[17]1'!$A$5:$E$1048576,3,0),0) | T19: =+IFERROR(VLOOKUP($A19,'[18]1'!$A$5:$E$1048576,3,0),0) | U19: =+IFERROR(VLOOKUP($A19,[19]Balans!$A$5:$E$1048576,3,0),0) | V19: =+IFERROR(VLOOKUP($A19,'[20]1'!$A$5:$E$1048576,3,0),0) | W19: =+IFERROR(VLOOKUP($A19,[21]Balance!$A$5:$E$1048576,3,0),0) | X19: =+IFERROR(VLOOKUP($A19,'[22]1'!$A$5:$E$1048576,3,0),0) | Y19: =+IFERROR(VLOOKUP($A19,[23]Лист1!$A$5:$E$1048576,3,0),0) | Z19: =+IFERROR(VLOOKUP($A19,'[24]1'!$A$5:$E$1048576,3,0),0) | AA19: =+IFERROR(VLOOKUP($A19,[25]Balance!$A$5:$E$1048576,3,0),0) | AB19: =+IFERROR(VLOOKUP($A19,'[26]1'!$A$5:$E$1048576,3,0),0) | AC19: =+IFERROR(VLOOKUP($A19,'[27]1'!$A$5:$E$1048576,3,0),0) | AD19: =+IFERROR(VLOOKUP($A19,'[28]1'!$A$5:$E$1048576,3,0),0) | AE19: =+IFERROR(VLOOKUP($A19,[29]Лист1!$A$5:$E$1048576,3,0),0) | AF19: =+IFERROR(VLOOKUP($A19,'[30]1'!$A$5:$E$1048576,3,0),0) | AG19: =+IFERROR(VLOOKUP($A19,'[31]1'!$A$5:$E$1048576,3,0),0) | AH19: =+IFERROR(VLOOKUP($A19,'[32]1-жадвал'!$A$5:$E$1048576,3,0),0) | AI19: =+IFERROR(VLOOKUP($A19,[33]Balance!$A$5:$E$1048576,3,0),0) | AJ19: =+IFERROR(VLOOKUP($A19,[34]Balance!$A$5:$E$1048576,3,0),0) | AK19: =+IFERROR(VLOOKUP($A19,'[35]1'!$A$5:$E$1048576,3,0),0)
A20: 6.3 | B20: Минус: Кўрилиши мумкин бўлган зарарларни қоплаш захираси | C20: =+IFERROR(VLOOKUP($A20,[1]Лист1!$A$5:$E$1048576,3,0),0) | D20: =+IFERROR(VLOOKUP($A20,'[2]1'!$A$5:$E$1048576,3,0),0) | E20: =+IFERROR(VLOOKUP($A20,'[3]1'!$A$5:$E$1048576,3,0),0) | F20: =+IFERROR(VLOOKUP($A20,[4]Balance!$A$5:$E$1048576,3,0),0) | G20: =+IFERROR(VLOOKUP($A20,'[5]1'!$A$5:$E$1048576,3,0),0) | H20: =+IFERROR(VLOOKUP($A20,[6]Balance!$A$5:$E$1048576,3,0),0) | I20: =+IFERROR(VLOOKUP($A20,[7]Balance!$A$5:$E$1048576,3,0),0) | J20: =+IFERROR(VLOOKUP($A20,'[8]1'!$A$5:$E$1048576,3,0),0) | K20: =+IFERROR(VLOOKUP($A20,'[9]1'!$A$5:$E$1048576,3,0),0) | L20: =+IFERROR(VLOOKUP($A20,'[10]1'!$A$5:$E$1048576,3,0),0) | M20: =+IFERROR(VLOOKUP($A20,'[11]1'!$A$5:$E$1048576,3,0),0) | N20: =+IFERROR(VLOOKUP($A20,[12]Balance!$A$5:$E$1048576,3,0),0) | O20: =+IFERROR(VLOOKUP($A20,'[13]1 т'!$A$5:$E$1048576,3,0),0) | P20: =+IFERROR(VLOOKUP($A20,[14]Balance!$A$5:$E$1048576,3,0),0) | Q20: =+IFERROR(VLOOKUP($A20,[15]Balance!$A$5:$E$1048576,3,0),0) | R20: =+IFERROR(VLOOKUP($A20,'[16]1'!$A$5:$E$1048576,3,0),0) | S20: =+IFERROR(VLOOKUP($A20,'[17]1'!$A$5:$E$1048576,3,0),0) | T20: =+IFERROR(VLOOKUP($A20,'[18]1'!$A$5:$E$1048576,3,0),0) | U20: =+IFERROR(VLOOKUP($A20,[19]Balans!$A$5:$E$1048576,3,0),0) | V20: =+IFERROR(VLOOKUP($A20,'[20]1'!$A$5:$E$1048576,3,0),0) | W20: =+IFERROR(VLOOKUP($A20,[21]Balance!$A$5:$E$1048576,3,0),0) | X20: =+IFERROR(VLOOKUP($A20,'[22]1'!$A$5:$E$1048576,3,0),0) | Y20: =+IFERROR(VLOOKUP($A20,[23]Лист1!$A$5:$E$1048576,3,0),0) | Z20: =+IFERROR(VLOOKUP($A20,'[24]1'!$A$5:$E$1048576,3,0),0) | AA20: =+IFERROR(VLOOKUP($A20,[25]Balance!$A$5:$E$1048576,3,0),0) | AB20: =+IFERROR(VLOOKUP($A20,'[26]1'!$A$5:$E$1048576,3,0),0) | AC20: =+IFERROR(VLOOKUP($A20,'[27]1'!$A$5:$E$1048576,3,0),0) | AD20: =+IFERROR(VLOOKUP($A20,'[28]1'!$A$5:$E$1048576,3,0),0) | AE20: =+IFERROR(VLOOKUP($A20,[29]Лист1!$A$5:$E$1048576,3,0),0) | AF20: =+IFERROR(VLOOKUP($A20,'[30]1'!$A$5:$E$1048576,3,0),0) | AG20: =+IFERROR(VLOOKUP($A20,'[31]1'!$A$5:$E$1048576,3,0),0) | AH20: =+IFERROR(VLOOKUP($A20,'[32]1-жадвал'!$A$5:$E$1048576,3,0),0) | AI20: =+IFERROR(VLOOKUP($A20,[33]Balance!$A$5:$E$1048576,3,0),0) | AJ20: =+IFERROR(VLOOKUP($A20,[34]Balance!$A$5:$E$1048576,3,0),0) | AK20: =+IFERROR(VLOOKUP($A20,'[35]1'!$A$5:$E$1048576,3,0),0)
A21: 7 | B21: РЕПО битимлари бўйича сотиб олинган қимматли қоғозлар, соф | C21: =+IFERROR(VLOOKUP($A21,[1]Лист1!$A$5:$E$1048576,3,0),0) | D21: =+IFERROR(VLOOKUP($A21,'[2]1'!$A$5:$E$1048576,3,0),0) | E21: =+IFERROR(VLOOKUP($A21,'[3]1'!$A$5:$E$1048576,3,0),0) | F21: =+IFERROR(VLOOKUP($A21,[4]Balance!$A$5:$E$1048576,3,0),0) | G21: =+IFERROR(VLOOKUP($A21,'[5]1'!$A$5:$E$1048576,3,0),0) | H21: =+IFERROR(VLOOKUP($A21,[6]Balance!$A$5:$E$1048576,3,0),0) | I21: =+IFERROR(VLOOKUP($A21,[7]Balance!$A$5:$E$1048576,3,0),0) | J21: =+IFERROR(VLOOKUP($A21,'[8]1'!$A$5:$E$1048576,3,0),0) | K21: =+IFERROR(VLOOKUP($A21,'[9]1'!$A$5:$E$1048576,3,0),0) | L21: =+IFERROR(VLOOKUP($A21,'[10]1'!$A$5:$E$1048576,3,0),0) | M21: =+IFERROR(VLOOKUP($A21,'[11]1'!$A$5:$E$1048576,3,0),0) | N21: =+IFERROR(VLOOKUP($A21,[12]Balance!$A$5:$E$1048576,3,0),0) | O21: =+IFERROR(VLOOKUP($A21,'[13]1 т'!$A$5:$E$1048576,3,0),0) | P21: =+IFERROR(VLOOKUP($A21,[14]Balance!$A$5:$E$1048576,3,0),0) | Q21: =+IFERROR(VLOOKUP($A21,[15]Balance!$A$5:$E$1048576,3,0),0) | R21: =+IFERROR(VLOOKUP($A21,'[16]1'!$A$5:$E$1048576,3,0),0) | S21: =+IFERROR(VLOOKUP($A21,'[17]1'!$A$5:$E$1048576,3,0),0) | T21: =+IFERROR(VLOOKUP($A21,'[18]1'!$A$5:$E$1048576,3,0),0) | U21: =+IFERROR(VLOOKUP($A21,[19]Balans!$A$5:$E$1048576,3,0),0) | V21: =+IFERROR(VLOOKUP($A21,'[20]1'!$A$5:$E$1048576,3,0),0) | W21: =+IFERROR(VLOOKUP($A21,[21]Balance!$A$5:$E$1048576,3,0),0) | X21: =+IFERROR(VLOOKUP($A21,'[22]1'!$A$5:$E$1048576,3,0),0) | Y21: =+IFERROR(VLOOKUP($A21,[23]Лист1!$A$5:$E$1048576,3,0),0) | Z21: =+IFERROR(VLOOKUP($A21,'[24]1'!$A$5:$E$1048576,3,0),0) | AA21: =+IFERROR(VLOOKUP($A21,[25]Balance!$A$5:$E$1048576,3,0),0) | AB21: =+IFERROR(VLOOKUP($A21,'[26]1'!$A$5:$E$1048576,3,0),0) | AC21: =+IFERROR(VLOOKUP($A21,'[27]1'!$A$5:$E$1048576,3,0),0) | AD21: =+IFERROR(VLOOKUP($A21,'[28]1'!$A$5:$E$1048576,3,0),0) | AE21: =+IFERROR(VLOOKUP($A21,[29]Лист1!$A$5:$E$1048576,3,0),0) | AF21: =+IFERROR(VLOOKUP($A21,'[30]1'!$A$5:$E$1048576,3,0),0) | AG21: =+IFERROR(VLOOKUP($A21,'[31]1'!$A$5:$E$1048576,3,0),0) | AH21: =+IFERROR(VLOOKUP($A21,'[32]1-жадвал'!$A$5:$E$1048576,3,0),0) | AI21: =+IFERROR(VLOOKUP($A21,[33]Balance!$A$5:$E$1048576,3,0),0) | AJ21: =+IFERROR(VLOOKUP($A21,[34]Balance!$A$5:$E$1048576,3,0),0) | AK21: =+IFERROR(VLOOKUP($A21,'[35]1'!$A$5:$E$1048576,3,0),0)
A22: 7.1 | B22: РЕПО битимлари бўйича сотиб олинган қимматли қоғозлар, брутто | C22: =+IFERROR(VLOOKUP($A22,[1]Лист1!$A$5:$E$1048576,3,0),0) | D22: =+IFERROR(VLOOKUP($A22,'[2]1'!$A$5:$E$1048576,3,0),0) | E22: =+IFERROR(VLOOKUP($A22,'[3]1'!$A$5:$E$1048576,3,0),0) | F22: =+IFERROR(VLOOKUP($A22,[4]Balance!$A$5:$E$1048576,3,0),0) | G22: =+IFERROR(VLOOKUP($A22,'[5]1'!$A$5:$E$1048576,3,0),0) | H22: =+IFERROR(VLOOKUP($A22,[6]Balance!$A$5:$E$1048576,3,0),0) | I22: =+IFERROR(VLOOKUP($A22,[7]Balance!$A$5:$E$1048576,3,0),0) | J22: =+IFERROR(VLOOKUP($A22,'[8]1'!$A$5:$E$1048576,3,0),0) | K22: =+IFERROR(VLOOKUP($A22,'[9]1'!$A$5:$E$1048576,3,0),0) | L22: =+IFERROR(VLOOKUP($A22,'[10]1'!$A$5:$E$1048576,3,0),0) | M22: =+IFERROR(VLOOKUP($A22,'[11]1'!$A$5:$E$1048576,3,0),0) | N22: =+IFERROR(VLOOKUP($A22,[12]Balance!$A$5:$E$1048576,3,0),0) | O22: =+IFERROR(VLOOKUP($A22,'[13]1 т'!$A$5:$E$1048576,3,0),0) | P22: =+IFERROR(VLOOKUP($A22,[14]Balance!$A$5:$E$1048576,3,0),0) | Q22: =+IFERROR(VLOOKUP($A22,[15]Balance!$A$5:$E$1048576,3,0),0) | R22: =+IFERROR(VLOOKUP($A22,'[16]1'!$A$5:$E$1048576,3,0),0) | S22: =+IFERROR(VLOOKUP($A22,'[17]1'!$A$5:$E$1048576,3,0),0) | T22: =+IFERROR(VLOOKUP($A22,'[18]1'!$A$5:$E$1048576,3,0),0) | U22: =+IFERROR(VLOOKUP($A22,[19]Balans!$A$5:$E$1048576,3,0),0) | V22: =+IFERROR(VLOOKUP($A22,'[20]1'!$A$5:$E$1048576,3,0),0) | W22: =+IFERROR(VLOOKUP($A22,[21]Balance!$A$5:$E$1048576,3,0),0) | X22: =+IFERROR(VLOOKUP($A22,'[22]1'!$A$5:$E$1048576,3,0),0) | Y22: =+IFERROR(VLOOKUP($A22,[23]Лист1!$A$5:$E$1048576,3,0),0) | Z22: =+IFERROR(VLOOKUP($A22,'[24]1'!$A$5:$E$1048576,3,0),0) | AA22: =+IFERROR(VLOOKUP($A22,[25]Balance!$A$5:$E$1048576,3,0),0) | AB22: =+IFERROR(VLOOKUP($A22,'[26]1'!$A$5:$E$1048576,3,0),0) | AC22: =+IFERROR(VLOOKUP($A22,'[27]1'!$A$5:$E$1048576,3,0),0) | AD22: =+IFERROR(VLOOKUP($A22,'[28]1'!$A$5:$E$1048576,3,0),0) | AE22: =+IFERROR(VLOOKUP($A22,[29]Лист1!$A$5:$E$1048576,3,0),0) | AF22: =+IFERROR(VLOOKUP($A22,'[30]1'!$A$5:$E$1048576,3,0),0) | AG22: =+IFERROR(VLOOKUP($A22,'[31]1'!$A$5:$E$1048576,3,0),0) | AH22: =+IFERROR(VLOOKUP($A22,'[32]1-жадвал'!$A$5:$E$1048576,3,0),0) | AI22: =+IFERROR(VLOOKUP($A22,[33]Balance!$A$5:$E$1048576,3,0),0) | AJ22: =+IFERROR(VLOOKUP($A22,[34]Balance!$A$5:$E$1048576,3,0),0) | AK22: =+IFERROR(VLOOKUP($A22,'[35]1'!$A$5:$E$1048576,3,0),0)
A23: 7.2 | B23: Минус: Кўрилиши мумкин бўлган зарарларни қоплаш захираси | C23: =+IFERROR(VLOOKUP($A23,[1]Лист1!$A$5:$E$1048576,3,0),0) | D23: =+IFERROR(VLOOKUP($A23,'[2]1'!$A$5:$E$1048576,3,0),0) | E23: =+IFERROR(VLOOKUP($A23,'[3]1'!$A$5:$E$1048576,3,0),0) | F23: =+IFERROR(VLOOKUP($A23,[4]Balance!$A$5:$E$1048576,3,0),0) | G23: =+IFERROR(VLOOKUP($A23,'[5]1'!$A$5:$E$1048576,3,0),0) | H23: =+IFERROR(VLOOKUP($A23,[6]Balance!$A$5:$E$1048576,3,0),0) | I23: =+IFERROR(VLOOKUP($A23,[7]Balance!$A$5:$E$1048576,3,0),0) | J23: =+IFERROR(VLOOKUP($A23,'[8]1'!$A$5:$E$1048576,3,0),0) | K23: =+IFERROR(VLOOKUP($A23,'[9]1'!$A$5:$E$1048576,3,0),0) | L23: =+IFERROR(VLOOKUP($A23,'[10]1'!$A$5:$E$1048576,3,0),0) | M23: =+IFERROR(VLOOKUP($A23,'[11]1'!$A$5:$E$1048576,3,0),0) | N23: =+IFERROR(VLOOKUP($A23,[12]Balance!$A$5:$E$1048576,3,0),0) | O23: =+IFERROR(VLOOKUP($A23,'[13]1 т'!$A$5:$E$1048576,3,0),0) | P23: =+IFERROR(VLOOKUP($A23,[14]Balance!$A$5:$E$1048576,3,0),0) | Q23: =+IFERROR(VLOOKUP($A23,[15]Balance!$A$5:$E$1048576,3,0),0) | R23: =+IFERROR(VLOOKUP($A23,'[16]1'!$A$5:$E$1048576,3,0),0) | S23: =+IFERROR(VLOOKUP($A23,'[17]1'!$A$5:$E$1048576,3,0),0) | T23: =+IFERROR(VLOOKUP($A23,'[18]1'!$A$5:$E$1048576,3,0),0) | U23: =+IFERROR(VLOOKUP($A23,[19]Balans!$A$5:$E$1048576,3,0),0) | V23: =+IFERROR(VLOOKUP($A23,'[20]1'!$A$5:$E$1048576,3,0),0) | W23: =+IFERROR(VLOOKUP($A23,[21]Balance!$A$5:$E$1048576,3,0),0) | X23: =+IFERROR(VLOOKUP($A23,'[22]1'!$A$5:$E$1048576,3,0),0) | Y23: =+IFERROR(VLOOKUP($A23,[23]Лист1!$A$5:$E$1048576,3,0),0) | Z23: =+IFERROR(VLOOKUP($A23,'[24]1'!$A$5:$E$1048576,3,0),0) | AA23: =+IFERROR(VLOOKUP($A23,[25]Balance!$A$5:$E$1048576,3,0),0) | AB23: =+IFERROR(VLOOKUP($A23,'[26]1'!$A$5:$E$1048576,3,0),0) | AC23: =+IFERROR(VLOOKUP($A23,'[27]1'!$A$5:$E$1048576,3,0),0) | AD23: =+IFERROR(VLOOKUP($A23,'[28]1'!$A$5:$E$1048576,3,0),0) | AE23: =+IFERROR(VLOOKUP($A23,[29]Лист1!$A$5:$E$1048576,3,0),0) | AF23: =+IFERROR(VLOOKUP($A23,'[30]1'!$A$5:$E$1048576,3,0),0) | AG23: =+IFERROR(VLOOKUP($A23,'[31]1'!$A$5:$E$1048576,3,0),0) | AH23: =+IFERROR(VLOOKUP($A23,'[32]1-жадвал'!$A$5:$E$1048576,3,0),0) | AI23: =+IFERROR(VLOOKUP($A23,[33]Balance!$A$5:$E$1048576,3,0),0) | AJ23: =+IFERROR(VLOOKUP($A23,[34]Balance!$A$5:$E$1048576,3,0),0) | AK23: =+IFERROR(VLOOKUP($A23,'[35]1'!$A$5:$E$1048576,3,0),0)
A24: 8 | B24: Кредит ва лизинг операциялари, соф | C24: =+IFERROR(VLOOKUP($A24,[1]Лист1!$A$5:$E$1048576,3,0),0) | D24: =+IFERROR(VLOOKUP($A24,'[2]1'!$A$5:$E$1048576,3,0),0) | E24: =+IFERROR(VLOOKUP($A24,'[3]1'!$A$5:$E$1048576,3,0),0) | F24: =+IFERROR(VLOOKUP($A24,[4]Balance!$A$5:$E$1048576,3,0),0) | G24: =+IFERROR(VLOOKUP($A24,'[5]1'!$A$5:$E$1048576,3,0),0) | H24: =+IFERROR(VLOOKUP($A24,[6]Balance!$A$5:$E$1048576,3,0),0) | I24: =+IFERROR(VLOOKUP($A24,[7]Balance!$A$5:$E$1048576,3,0),0) | J24: =+IFERROR(VLOOKUP($A24,'[8]1'!$A$5:$E$1048576,3,0),0) | K24: =+IFERROR(VLOOKUP($A24,'[9]1'!$A$5:$E$1048576,3,0),0) | L24: =+IFERROR(VLOOKUP($A24,'[10]1'!$A$5:$E$1048576,3,0),0) | M24: =+IFERROR(VLOOKUP($A24,'[11]1'!$A$5:$E$1048576,3,0),0) | N24: =+IFERROR(VLOOKUP($A24,[12]Balance!$A$5:$E$1048576,3,0),0) | O24: =+IFERROR(VLOOKUP($A24,'[13]1 т'!$A$5:$E$1048576,3,0),0) | P24: =+IFERROR(VLOOKUP($A24,[14]Balance!$A$5:$E$1048576,3,0),0) | Q24: =+IFERROR(VLOOKUP($A24,[15]Balance!$A$5:$E$1048576,3,0),0) | R24: =+IFERROR(VLOOKUP($A24,'[16]1'!$A$5:$E$1048576,3,0),0) | S24: =+IFERROR(VLOOKUP($A24,'[17]1'!$A$5:$E$1048576,3,0),0) | T24: =+IFERROR(VLOOKUP($A24,'[18]1'!$A$5:$E$1048576,3,0),0) | U24: =+IFERROR(VLOOKUP($A24,[19]Balans!$A$5:$E$1048576,3,0),0) | V24: =+IFERROR(VLOOKUP($A24,'[20]1'!$A$5:$E$1048576,3,0),0) | W24: =+IFERROR(VLOOKUP($A24,[21]Balance!$A$5:$E$1048576,3,0),0) | X24: =+IFERROR(VLOOKUP($A24,'[22]1'!$A$5:$E$1048576,3,0),0) | Y24: =+IFERROR(VLOOKUP($A24,[23]Лист1!$A$5:$E$1048576,3,0),0) | Z24: =+IFERROR(VLOOKUP($A24,'[24]1'!$A$5:$E$1048576,3,0),0) | AA24: =+IFERROR(VLOOKUP($A24,[25]Balance!$A$5:$E$1048576,3,0),0) | AB24: =+IFERROR(VLOOKUP($A24,'[26]1'!$A$5:$E$1048576,3,0),0) | AC24: =+IFERROR(VLOOKUP($A24,'[27]1'!$A$5:$E$1048576,3,0),0) | AD24: =+IFERROR(VLOOKUP($A24,'[28]1'!$A$5:$E$1048576,3,0),0) | AE24: =+IFERROR(VLOOKUP($A24,[29]Лист1!$A$5:$E$1048576,3,0),0) | AF24: =+IFERROR(VLOOKUP($A24,'[30]1'!$A$5:$E$1048576,3,0),0) | AG24: =+IFERROR(VLOOKUP($A24,'[31]1'!$A$5:$E$1048576,3,0),0) | AH24: =+IFERROR(VLOOKUP($A24,'[32]1-жадвал'!$A$5:$E$1048576,3,0),0) | AI24: =+IFERROR(VLOOKUP($A24,[33]Balance!$A$5:$E$1048576,3,0),0) | AJ24: =+IFERROR(VLOOKUP($A24,[34]Balance!$A$5:$E$1048576,3,0),0) | AK24: =+IFERROR(VLOOKUP($A24,'[35]1'!$A$5:$E$1048576,3,0),0)
A25: 8.1 | B25: Кредит ва лизинг операциялари, брутто | C25: =+IFERROR(VLOOKUP($A25,[1]Лист1!$A$5:$E$1048576,3,0),0) | D25: =+IFERROR(VLOOKUP($A25,'[2]1'!$A$5:$E$1048576,3,0),0) | E25: =+IFERROR(VLOOKUP($A25,'[3]1'!$A$5:$E$1048576,3,0),0) | F25: =+IFERROR(VLOOKUP($A25,[4]Balance!$A$5:$E$1048576,3,0),0) | G25: =+IFERROR(VLOOKUP($A25,'[5]1'!$A$5:$E$1048576,3,0),0) | H25: =+IFERROR(VLOOKUP($A25,[6]Balance!$A$5:$E$1048576,3,0),0) | I25: =+IFERROR(VLOOKUP($A25,[7]Balance!$A$5:$E$1048576,3,0),0) | J25: =+IFERROR(VLOOKUP($A25,'[8]1'!$A$5:$E$1048576,3,0),0) | K25: =+IFERROR(VLOOKUP($A25,'[9]1'!$A$5:$E$1048576,3,0),0) | L25: =+IFERROR(VLOOKUP($A25,'[10]1'!$A$5:$E$1048576,3,0),0) | M25: =+IFERROR(VLOOKUP($A25,'[11]1'!$A$5:$E$1048576,3,0),0) | N25: =+IFERROR(VLOOKUP($A25,[12]Balance!$A$5:$E$1048576,3,0),0) | O25: =+IFERROR(VLOOKUP($A25,'[13]1 т'!$A$5:$E$1048576,3,0),0) | P25: =+IFERROR(VLOOKUP($A25,[14]Balance!$A$5:$E$1048576,3,0),0) | Q25: =+IFERROR(VLOOKUP($A25,[15]Balance!$A$5:$E$1048576,3,0),0) | R25: =+IFERROR(VLOOKUP($A25,'[16]1'!$A$5:$E$1048576,3,0),0) | S25: =+IFERROR(VLOOKUP($A25,'[17]1'!$A$5:$E$1048576,3,0),0) | T25: =+IFERROR(VLOOKUP($A25,'[18]1'!$A$5:$E$1048576,3,0),0) | U25: =+IFERROR(VLOOKUP($A25,[19]Balans!$A$5:$E$1048576,3,0),0) | V25: =+IFERROR(VLOOKUP($A25,'[20]1'!$A$5:$E$1048576,3,0),0) | W25: =+IFERROR(VLOOKUP($A25,[21]Balance!$A$5:$E$1048576,3,0),0) | X25: =+IFERROR(VLOOKUP($A25,'[22]1'!$A$5:$E$1048576,3,0),0) | Y25: =+IFERROR(VLOOKUP($A25,[23]Лист1!$A$5:$E$1048576,3,0),0) | Z25: =+IFERROR(VLOOKUP($A25,'[24]1'!$A$5:$E$1048576,3,0),0) | AA25: =+IFERROR(VLOOKUP($A25,[25]Balance!$A$5:$E$1048576,3,0),0) | AB25: =+IFERROR(VLOOKUP($A25,'[26]1'!$A$5:$E$1048576,3,0),0) | AC25: =+IFERROR(VLOOKUP($A25,'[27]1'!$A$5:$E$1048576,3,0),0) | AD25: =+IFERROR(VLOOKUP($A25,'[28]1'!$A$5:$E$1048576,3,0),0) | AE25: =+IFERROR(VLOOKUP($A25,[29]Лист1!$A$5:$E$1048576,3,0),0) | AF25: =+IFERROR(VLOOKUP($A25,'[30]1'!$A$5:$E$1048576,3,0),0) | AG25: =+IFERROR(VLOOKUP($A25,'[31]1'!$A$5:$E$1048576,3,0),0) | AH25: =+IFERROR(VLOOKUP($A25,'[32]1-жадвал'!$A$5:$E$1048576,3,0),0) | AI25: =+IFERROR(VLOOKUP($A25,[33]Balance!$A$5:$E$1048576,3,0),0) | AJ25: =+IFERROR(VLOOKUP($A25,[34]Balance!$A$5:$E$1048576,3,0),0) | AK25: =+IFERROR(VLOOKUP($A25,'[35]1'!$A$5:$E$1048576,3,0),0)
A26: 8.2 | B26: Минус: Кўрилиши мумкин бўлган зарарларни қоплаш захираси | C26: =+IFERROR(VLOOKUP($A26,[1]Лист1!$A$5:$E$1048576,3,0),0) | D26: =+IFERROR(VLOOKUP($A26,'[2]1'!$A$5:$E$1048576,3,0),0) | E26: =+IFERROR(VLOOKUP($A26,'[3]1'!$A$5:$E$1048576,3,0),0) | F26: =+IFERROR(VLOOKUP($A26,[4]Balance!$A$5:$E$1048576,3,0),0) | G26: =+IFERROR(VLOOKUP($A26,'[5]1'!$A$5:$E$1048576,3,0),0) | H26: =+IFERROR(VLOOKUP($A26,[6]Balance!$A$5:$E$1048576,3,0),0) | I26: =+IFERROR(VLOOKUP($A26,[7]Balance!$A$5:$E$1048576,3,0),0) | J26: =+IFERROR(VLOOKUP($A26,'[8]1'!$A$5:$E$1048576,3,0),0) | K26: =+IFERROR(VLOOKUP($A26,'[9]1'!$A$5:$E$1048576,3,0),0) | L26: =+IFERROR(VLOOKUP($A26,'[10]1'!$A$5:$E$1048576,3,0),0) | M26: =+IFERROR(VLOOKUP($A26,'[11]1'!$A$5:$E$1048576,3,0),0) | N26: =+IFERROR(VLOOKUP($A26,[12]Balance!$A$5:$E$1048576,3,0),0) | O26: =+IFERROR(VLOOKUP($A26,'[13]1 т'!$A$5:$E$1048576,3,0),0) | P26: =+IFERROR(VLOOKUP($A26,[14]Balance!$A$5:$E$1048576,3,0),0) | Q26: =+IFERROR(VLOOKUP($A26,[15]Balance!$A$5:$E$1048576,3,0),0) | R26: =+IFERROR(VLOOKUP($A26,'[16]1'!$A$5:$E$1048576,3,0),0) | S26: =+IFERROR(VLOOKUP($A26,'[17]1'!$A$5:$E$1048576,3,0),0) | T26: =+IFERROR(VLOOKUP($A26,'[18]1'!$A$5:$E$1048576,3,0),0) | U26: =+IFERROR(VLOOKUP($A26,[19]Balans!$A$5:$E$1048576,3,0),0) | V26: =+IFERROR(VLOOKUP($A26,'[20]1'!$A$5:$E$1048576,3,0),0) | W26: =+IFERROR(VLOOKUP($A26,[21]Balance!$A$5:$E$1048576,3,0),0) | X26: =+IFERROR(VLOOKUP($A26,'[22]1'!$A$5:$E$1048576,3,0),0) | Y26: =+IFERROR(VLOOKUP($A26,[23]Лист1!$A$5:$E$1048576,3,0),0) | Z26: =+IFERROR(VLOOKUP($A26,'[24]1'!$A$5:$E$1048576,3,0),0) | AA26: =+IFERROR(VLOOKUP($A26,[25]Balance!$A$5:$E$1048576,3,0),0) | AB26: =+IFERROR(VLOOKUP($A26,'[26]1'!$A$5:$E$1048576,3,0),0) | AC26: =+IFERROR(VLOOKUP($A26,'[27]1'!$A$5:$E$1048576,3,0),0) | AD26: =+IFERROR(VLOOKUP($A26,'[28]1'!$A$5:$E$1048576,3,0),0) | AE26: =+IFERROR(VLOOKUP($A26,[29]Лист1!$A$5:$E$1048576,3,0),0) | AF26: =+IFERROR(VLOOKUP($A26,'[30]1'!$A$5:$E$1048576,3,0),0) | AG26: =+IFERROR(VLOOKUP($A26,'[31]1'!$A$5:$E$1048576,3,0),0) | AH26: =+IFERROR(VLOOKUP($A26,'[32]1-жадвал'!$A$5:$E$1048576,3,0),0) | AI26: =+IFERROR(VLOOKUP($A26,[33]Balance!$A$5:$E$1048576,3,0),0) | AJ26: =+IFERROR(VLOOKUP($A26,[34]Balance!$A$5:$E$1048576,3,0),0) | AK26: =+IFERROR(VLOOKUP($A26,'[35]1'!$A$5:$E$1048576,3,0),0)
A27: 9 | B27: Молиявий инструментлар бўйича мижозларнинг мажбуриятлари, соф | C27: =+IFERROR(VLOOKUP($A27,[1]Лист1!$A$5:$E$1048576,3,0),0) | D27: =+IFERROR(VLOOKUP($A27,'[2]1'!$A$5:$E$1048576,3,0),0) | E27: =+IFERROR(VLOOKUP($A27,'[3]1'!$A$5:$E$1048576,3,0),0) | F27: =+IFERROR(VLOOKUP($A27,[4]Balance!$A$5:$E$1048576,3,0),0) | G27: =+IFERROR(VLOOKUP($A27,'[5]1'!$A$5:$E$1048576,3,0),0) | H27: =+IFERROR(VLOOKUP($A27,[6]Balance!$A$5:$E$1048576,3,0),0) | I27: =+IFERROR(VLOOKUP($A27,[7]Balance!$A$5:$E$1048576,3,0),0) | J27: =+IFERROR(VLOOKUP($A27,'[8]1'!$A$5:$E$1048576,3,0),0) | K27: =+IFERROR(VLOOKUP($A27,'[9]1'!$A$5:$E$1048576,3,0),0) | L27: =+IFERROR(VLOOKUP($A27,'[10]1'!$A$5:$E$1048576,3,0),0) | M27: =+IFERROR(VLOOKUP($A27,'[11]1'!$A$5:$E$1048576,3,0),0) | N27: =+IFERROR(VLOOKUP($A27,[12]Balance!$A$5:$E$1048576,3,0),0) | O27: =+IFERROR(VLOOKUP($A27,'[13]1 т'!$A$5:$E$1048576,3,0),0) | P27: =+IFERROR(VLOOKUP($A27,[14]Balance!$A$5:$E$1048576,3,0),0) | Q27: =+IFERROR(VLOOKUP($A27,[15]Balance!$A$5:$E$1048576,3,0),0) | R27: =+IFERROR(VLOOKUP($A27,'[16]1'!$A$5:$E$1048576,3,0),0) | S27: =+IFERROR(VLOOKUP($A27,'[17]1'!$A$5:$E$1048576,3,0),0) | T27: =+IFERROR(VLOOKUP($A27,'[18]1'!$A$5:$E$1048576,3,0),0) | U27: =+IFERROR(VLOOKUP($A27,[19]Balans!$A$5:$E$1048576,3,0),0) | V27: =+IFERROR(VLOOKUP($A27,'[20]1'!$A$5:$E$1048576,3,0),0) | W27: =+IFERROR(VLOOKUP($A27,[21]Balance!$A$5:$E$1048576,3,0),0) | X27: =+IFERROR(VLOOKUP($A27,'[22]1'!$A$5:$E$1048576,3,0),0) | Y27: =+IFERROR(VLOOKUP($A27,[23]Лист1!$A$5:$E$1048576,3,0),0) | Z27: =+IFERROR(VLOOKUP($A27,'[24]1'!$A$5:$E$1048576,3,0),0) | AA27: =+IFERROR(VLOOKUP($A27,[25]Balance!$A$5:$E$1048576,3,0),0) | AB27: =+IFERROR(VLOOKUP($A27,'[26]1'!$A$5:$E$1048576,3,0),0) | AC27: =+IFERROR(VLOOKUP($A27,'[27]1'!$A$5:$E$1048576,3,0),0) | AD27: =+IFERROR(VLOOKUP($A27,'[28]1'!$A$5:$E$1048576,3,0),0) | AE27: =+IFERROR(VLOOKUP($A27,[29]Лист1!$A$5:$E$1048576,3,0),0) | AF27: =+IFERROR(VLOOKUP($A27,'[30]1'!$A$5:$E$1048576,3,0),0) | AG27: =+IFERROR(VLOOKUP($A27,'[31]1'!$A$5:$E$1048576,3,0),0) | AH27: =+IFERROR(VLOOKUP($A27,'[32]1-жадвал'!$A$5:$E$1048576,3,0),0) | AI27: =+IFERROR(VLOOKUP($A27,[33]Balance!$A$5:$E$1048576,3,0),0) | AJ27: =+IFERROR(VLOOKUP($A27,[34]Balance!$A$5:$E$1048576,3,0),0) | AK27: =+IFERROR(VLOOKUP($A27,'[35]1'!$A$5:$E$1048576,3,0),0)
A28: 9.1 | B28: Молиявий инструментлар бўйича мижозларнинг мажбуриятлари, брутто | C28: =+IFERROR(VLOOKUP($A28,[1]Лист1!$A$5:$E$1048576,3,0),0) | D28: =+IFERROR(VLOOKUP($A28,'[2]1'!$A$5:$E$1048576,3,0),0) | E28: =+IFERROR(VLOOKUP($A28,'[3]1'!$A$5:$E$1048576,3,0),0) | F28: =+IFERROR(VLOOKUP($A28,[4]Balance!$A$5:$E$1048576,3,0),0) | G28: =+IFERROR(VLOOKUP($A28,'[5]1'!$A$5:$E$1048576,3,0),0) | H28: =+IFERROR(VLOOKUP($A28,[6]Balance!$A$5:$E$1048576,3,0),0) | I28: =+IFERROR(VLOOKUP($A28,[7]Balance!$A$5:$E$1048576,3,0),0) | J28: =+IFERROR(VLOOKUP($A28,'[8]1'!$A$5:$E$1048576,3,0),0) | K28: =+IFERROR(VLOOKUP($A28,'[9]1'!$A$5:$E$1048576,3,0),0) | L28: =+IFERROR(VLOOKUP($A28,'[10]1'!$A$5:$E$1048576,3,0),0) | M28: =+IFERROR(VLOOKUP($A28,'[11]1'!$A$5:$E$1048576,3,0),0) | N28: =+IFERROR(VLOOKUP($A28,[12]Balance!$A$5:$E$1048576,3,0),0) | O28: =+IFERROR(VLOOKUP($A28,'[13]1 т'!$A$5:$E$1048576,3,0),0) | P28: =+IFERROR(VLOOKUP($A28,[14]Balance!$A$5:$E$1048576,3,0),0) | Q28: =+IFERROR(VLOOKUP($A28,[15]Balance!$A$5:$E$1048576,3,0),0) | R28: =+IFERROR(VLOOKUP($A28,'[16]1'!$A$5:$E$1048576,3,0),0) | S28: =+IFERROR(VLOOKUP($A28,'[17]1'!$A$5:$E$1048576,3,0),0) | T28: =+IFERROR(VLOOKUP($A28,'[18]1'!$A$5:$E$1048576,3,0),0) | U28: =+IFERROR(VLOOKUP($A28,[19]Balans!$A$5:$E$1048576,3,0),0) | V28: =+IFERROR(VLOOKUP($A28,'[20]1'!$A$5:$E$1048576,3,0),0) | W28: =+IFERROR(VLOOKUP($A28,[21]Balance!$A$5:$E$1048576,3,0),0) | X28: =+IFERROR(VLOOKUP($A28,'[22]1'!$A$5:$E$1048576,3,0),0) | Y28: =+IFERROR(VLOOKUP($A28,[23]Лист1!$A$5:$E$1048576,3,0),0) | Z28: =+IFERROR(VLOOKUP($A28,'[24]1'!$A$5:$E$1048576,3,0),0) | AA28: =+IFERROR(VLOOKUP($A28,[25]Balance!$A$5:$E$1048576,3,0),0) | AB28: =+IFERROR(VLOOKUP($A28,'[26]1'!$A$5:$E$1048576,3,0),0) | AC28: =+IFERROR(VLOOKUP($A28,'[27]1'!$A$5:$E$1048576,3,0),0) | AD28: =+IFERROR(VLOOKUP($A28,'[28]1'!$A$5:$E$1048576,3,0),0) | AE28: =+IFERROR(VLOOKUP($A28,[29]Лист1!$A$5:$E$1048576,3,0),0) | AF28: =+IFERROR(VLOOKUP($A28,'[30]1'!$A$5:$E$1048576,3,0),0) | AG28: =+IFERROR(VLOOKUP($A28,'[31]1'!$A$5:$E$1048576,3,0),0) | AH28: =+IFERROR(VLOOKUP($A28,'[32]1-жадвал'!$A$5:$E$1048576,3,0),0) | AI28: =+IFERROR(VLOOKUP($A28,[33]Balance!$A$5:$E$1048576,3,0),0) | AJ28: =+IFERROR(VLOOKUP($A28,[34]Balance!$A$5:$E$1048576,3,0),0) | AK28: =+IFERROR(VLOOKUP($A28,'[35]1'!$A$5:$E$1048576,3,0),0)
A29: 9.2 | B29: Минус: Кўрилиши мумкин бўлган зарарларни қоплаш захираси | C29: =+IFERROR(VLOOKUP($A29,[1]Лист1!$A$5:$E$1048576,3,0),0) | D29: =+IFERROR(VLOOKUP($A29,'[2]1'!$A$5:$E$1048576,3,0),0) | E29: =+IFERROR(VLOOKUP($A29,'[3]1'!$A$5:$E$1048576,3,0),0) | F29: =+IFERROR(VLOOKUP($A29,[4]Balance!$A$5:$E$1048576,3,0),0) | G29: =+IFERROR(VLOOKUP($A29,'[5]1'!$A$5:$E$1048576,3,0),0) | H29: =+IFERROR(VLOOKUP($A29,[6]Balance!$A$5:$E$1048576,3,0),0) | I29: =+IFERROR(VLOOKUP($A29,[7]Balance!$A$5:$E$1048576,3,0),0) | J29: =+IFERROR(VLOOKUP($A29,'[8]1'!$A$5:$E$1048576,3,0),0) | K29: =+IFERROR(VLOOKUP($A29,'[9]1'!$A$5:$E$1048576,3,0),0) | L29: =+IFERROR(VLOOKUP($A29,'[10]1'!$A$5:$E$1048576,3,0),0) | M29: =+IFERROR(VLOOKUP($A29,'[11]1'!$A$5:$E$1048576,3,0),0) | N29: =+IFERROR(VLOOKUP($A29,[12]Balance!$A$5:$E$1048576,3,0),0) | O29: =+IFERROR(VLOOKUP($A29,'[13]1 т'!$A$5:$E$1048576,3,0),0) | P29: =+IFERROR(VLOOKUP($A29,[14]Balance!$A$5:$E$1048576,3,0),0) | Q29: =+IFERROR(VLOOKUP($A29,[15]Balance!$A$5:$E$1048576,3,0),0) | R29: =+IFERROR(VLOOKUP($A29,'[16]1'!$A$5:$E$1048576,3,0),0) | S29: =+IFERROR(VLOOKUP($A29,'[17]1'!$A$5:$E$1048576,3,0),0) | T29: =+IFERROR(VLOOKUP($A29,'[18]1'!$A$5:$E$1048576,3,0),0) | U29: =+IFERROR(VLOOKUP($A29,[19]Balans!$A$5:$E$1048576,3,0),0) | V29: =+IFERROR(VLOOKUP($A29,'[20]1'!$A$5:$E$1048576,3,0),0) | W29: =+IFERROR(VLOOKUP($A29,[21]Balance!$A$5:$E$1048576,3,0),0) | X29: =+IFERROR(VLOOKUP($A29,'[22]1'!$A$5:$E$1048576,3,0),0) | Y29: =+IFERROR(VLOOKUP($A29,[23]Лист1!$A$5:$E$1048576,3,0),0) | Z29: =+IFERROR(VLOOKUP($A29,'[24]1'!$A$5:$E$1048576,3,0),0) | AA29: =+IFERROR(VLOOKUP($A29,[25]Balance!$A$5:$E$1048576,3,0),0) | AB29: =+IFERROR(VLOOKUP($A29,'[26]1'!$A$5:$E$1048576,3,0),0) | AC29: =+IFERROR(VLOOKUP($A29,'[27]1'!$A$5:$E$1048576,3,0),0) | AD29: =+IFERROR(VLOOKUP($A29,'[28]1'!$A$5:$E$1048576,3,0),0) | AE29: =+IFERROR(VLOOKUP($A29,[29]Лист1!$A$5:$E$1048576,3,0),0) | AF29: =+IFERROR(VLOOKUP($A29,'[30]1'!$A$5:$E$1048576,3,0),0) | AG29: =+IFERROR(VLOOKUP($A29,'[31]1'!$A$5:$E$1048576,3,0),0) | AH29: =+IFERROR(VLOOKUP($A29,'[32]1-жадвал'!$A$5:$E$1048576,3,0),0) | AI29: =+IFERROR(VLOOKUP($A29,[33]Balance!$A$5:$E$1048576,3,0),0) | AJ29: =+IFERROR(VLOOKUP($A29,[34]Balance!$A$5:$E$1048576,3,0),0) | AK29: =+IFERROR(VLOOKUP($A29,'[35]1'!$A$5:$E$1048576,3,0),0)
